Workbook
Name SCEN_SWITCH: Assumptions!$C$5
Name WACC_USED: Assumptions!$C$82
Name WACC_CALC: Assumptions!$C$80
Name TERM_G: Assumptions!$C$83
Name KE: Assumptions!$C$78
Name KD: Assumptions!$C$79
Name RF_RATE: Assumptions!$C$71
Name ERP: Assumptions!$C$72
Name BETA_U: Assumptions!$C$73
Name TAX_RATE_Y1: Assumptions!$C$33
Name PAYOUT_Y1: Assumptions!$C$53
Name MIN_CASH_PCT: Assumptions!$C$57
Name SHARES_DIL: Equity_Roll!$C$21
Name DCF_PS: DCF!$D$25
Name FCFE_PS: FCFE!$D$18

Sheet Cover
B2: 中芯国际 (00981.HK) — 机构级估值模型
B3: 中芯国际 | 港股自动兜底建模(东财HKF10+腾讯行情; 财报币种美元)
B5: 模型构建日期 | C5: 2026-08-17 (行情基准日: 2026-08-17收盘; FIN调度/WACC做实/年中折现; FIN迭代展开消除循环引用)
B6: 经营货币 / 单位 | C6: 美元(财报口径) / 百万元 (每股数据为美元; 港元现价按fx折算)
B7: 市场口径 (港股) | C7: 无单日涨跌停限制(A股为±10%/20%, 口径差异不影响模型公式); 财务与估值为财报币种口径(见上行), 港元现价/总市值按配置fx折算, PE-TTM为港元行情口径仅供对照; 历史三表=东财HKF10(IFRS科目映射, 现金流量表按隐含汇率折算回财报币种)
B8: 颜色规范 | C8: 蓝色=输入/假设 | 黑色=公式 | 绿色=外部数据/链接 | 红色=警告
B9: ✓ 迭代展开(无循环引用) | C9: 原循环链(利息=平均债务余额×利率→净利→现金流→sweep→债务余额→利息)已在FIN页表内显式展开4轮(第1轮期初余额计息, 第k轮按(期初+上轮期末)/2×利率重算), 末轮输出供IS/CF/BS引用。全簿无任何循环引用, 无需开启迭代计算; 收敛残差<0.01(见FIN页残差行/Checks第11项), Excel/WPS/LibreOffice重算结果一致
B11: —— 关键市场数据 ——
B12: 现价 (元) | C12: =Assumptions!C7
B13: 总股本 (百万股) | C13: =Assumptions!C8
B14: 总市值 (百万元) | C14: =Assumptions!C9
B15: 一致预期 2026E 营收/归母 (百万) | C15: ="营收"&TEXT(Assumptions!C12,"#,##0")&" / 归母"&TEXT(Assumptions!C13,"#,##0")&" (自动推导(无一致预期输入): 最近年报收入×(1+YoY+16.2%)退坡; 建议手工填入)"
B17: —— 模型输出 (随情景开关联动) ——
B18: 当前情景 | C18: =Scenarios!C3
B19: 模型2026E营收 (百万) | C19: =IS!E4
B20: 模型2026E归母 (百万) | C20: =IS!E20
B21: WACC 计算值/采用值 | C21: =TEXT(Assumptions!C80,"0.00%")&" / "&TEXT(Assumptions!C82,"0.00%")
B22: DCF每股价值-基准 (元) | C22: =DCF!D25
B23: DCF每股-熊/基/牛 (元) | C23: =TEXT(Scenarios!B12,"0.00")&" / "&TEXT(Scenarios!B21,"0.00")&" / "&TEXT(Scenarios!B31,"0.00")
B24: 相对估值区间 (元) | C24: =TEXT(Relative_Val!C12,"0.00")&" ~ "&TEXT(Relative_Val!C13,"0.00")
B25: 综合参考区间 (元, Summary页) | C25: =TEXT(Summary!C12,"0.00")&" ~ "&TEXT(Summary!D12,"0.00")
B26: Checks校验 | C26: =Checks!F24
B28: —— 关键建模处理 (分析师注记) ——
B29: 1. FIN页债务调度: 资金缺口=MAX(0,期初现金+经营CF+投资CF+计划分红+计划还款+利息-最低现金)→revolver新增借款; 超额现金先sweep偿还短借/长借, 债务清零后溢出购买理财(交易性金融资产); 货币资金=最低现金(收入×60%), 杜绝"高现金+高借款"并存;
B30: 2. 利息=四档债务各自(期初+期末)/2平均余额×分档利率; 该循环依赖已在FIN页"迭代展开"区表内展开4轮(与外部不动点法同构且实测6轮内收敛至1e-8, 4轮充足), 末轮输出供IS/CF/BS引用; 全簿无循环引用, 无需开启迭代计算, LibreOffice headless可直接重算验收;
B31: 3. BS配平项由货币资金改为FIN页revolver新增借款/现金sweep; 历史尾差已并入"其他权益项目(轧差)"清零, 配平差额全期恒=0(容差0.01);
B32: 4. WACC做实: 可比公司βl按各自D/E与税率unlever取中位数(Relative_Val页L-O列), 按公司市值口径目标结构relever; Wd=最近年报末有息负债/(有息负债+总市值); 采用值=IF(override="",计算值,override), 下游全部引用采用值;
B33: 5. DCF年中折现: 估值基准日2026-08-17, t=0.5/1.5/.../4.5; EV→Equity桥含货币资金/交易性金融资产/其他权益工具投资/有息负债;
B34: 6. CF口径: 利息支出经营活动加回、筹资活动列"偿付利息"; 投资活动含"理财净变动"行;
B35: 7. 权益滚动: Equity_Roll页逐项滚动, 盈余公积按归母计提; 稀释股数=总股本+稀释工具占位; Summary页为football field区间汇总;
B36: 8. 预测期资产减值/投资收益等非经常项简化为固定小额(Assumptions"其他经营损益"), 以保证三表严格配平;
B37: 9. 分产品历史收入=产品占比×总收入; 预测按"量×价"驱动并受情景开关调整; 预测期(2026E-2030E)所有单元格均为公式, 硬编码仅限历史实际值(绿色)与蓝色假设输入;
B39: —— 数据来源 ——
B40: 历史三表: 东方财富F10 (2023A-2025A年报); 分产品结构: 东财F10主营构成/招股书/券商深度报告(以配置"依据"字段为准);
... B44: 免责声明: 本模型仅为研究学习用途, 所有预测基于公开信息与主观假设, 不构成任何投资建议或证券买卖要约。历史数据虽经核对来源, 仍可能存在口径差异或错误; 预测存在重大不确定性。使用者应自行判断并承担风险。

Sheet Summary
A1: 中芯国际 — Summary 估值结论汇总 (Football Field)
A2: 单位: 元/股 | 各方法估值区间与现价对比; DCF基准=主模型当前输出(随情景开关联动), 熊/牛为简化法区间
A4: 估值方法 | B4: 口径 | C4: 低(元) | D4: 高(元) | E4: 中点(元) | F4: 中点vs现价 | G4: 备注
A5: DCF绝对估值 — 基准 | B5: 主模型(当前情景) | C5: =DCF!D25 | D5: =DCF!D25 | E5: =(C5+D5)/2 | F5: =E5/Assumptions!$C$7-1 | G5: FCFF+Gordon终值, 年中折现, WACC采用值
A6: DCF绝对估值 — 熊市 | B6: 简化净利率法 | C6: =Scenarios!B12 | D6: =Scenarios!B12 | E6: =(C6+D6)/2 | F6: =E6/Assumptions!$C$7-1 | G6: 分部增速-15pct/净利率-3pct
A7: DCF绝对估值 — 牛市 | B7: 简化净利率法 | C7: =Scenarios!B31 | D7: =Scenarios!B31 | E7: =(C7+D7)/2 | F7: =E7/Assumptions!$C$7-1 | G7: 分部增速+10pct/净利率+1.5pct
A8: 相对估值 — 模型2026E归母 | B8: PE 25x ~ 可比中位 | C8: =Relative_Val!C12 | D8: =Relative_Val!C13 | E8: =(C8+D8)/2 | F8: =E8/Assumptions!$C$7-1 | G8: 模型基准2026E归母×目标PE带
A9: 相对估值 — 一致预期2026E归母 | B9: PE 25x ~ 可比中位 | C9: =Relative_Val!C14 | D9: =Relative_Val!D14 | E9: =(C9+D9)/2 | F9: =E9/Assumptions!$C$7-1 | G9: 一致预期8.0亿×目标PE带
A10: FCFE股权现金流 — 基准 | B10: Ke折现(股权口径) | C10: =FCFE!D18 | D10: =FCFE!D18 | E10: =(C10+D10)/2 | F10: =E10/Assumptions!$C$7-1 | G10: FCFE=归母+D&A-ΔNWC-Capex+净新增借款(FIN调度), 与FCFF双视图对照
A11: 现价 (2026-08-17) | C11: =Assumptions!$C$7 | D11: =Assumptions!$C$7 | E11: =Assumptions!$C$7
A12: 综合参考区间(全方法包络) | C12: =MIN(C5:C10) | D12: =MAX(D5:D10) | E12: =(C12+D12)/2 | F12: =E12/Assumptions!$C$7-1 | G12: 熊简化法DCF下限 ~ 牛简化法/相对估值上限的包络
A14: 区间可视化 (每个▮≈10元, 起点=区间低值)
A15: 方法 | B15: 区间条(低→高, 括号为现价相对位置)
A16: DCF绝对估值 — 基准 | B16: =REPT("▮",MAX(1,ROUND((D5-C5)/10,0)))&" ["&TEXT(C5,"0")&"—"&TEXT(D5,"0")&"]"
A17: DCF绝对估值 — 熊市 | B17: =REPT("▮",MAX(1,ROUND((D6-C6)/10,0)))&" ["&TEXT(C6,"0")&"—"&TEXT(D6,"0")&"]"
A18: DCF绝对估值 — 牛市 | B18: =REPT("▮",MAX(1,ROUND((D7-C7)/10,0)))&" ["&TEXT(C7,"0")&"—"&TEXT(D7,"0")&"]"
A19: 相对估值 — 模型2026E归母 | B19: =REPT("▮",MAX(1,ROUND((D8-C8)/10,0)))&" ["&TEXT(C8,"0")&"—"&TEXT(D8,"0")&"]"
A20: 相对估值 — 一致预期2026E归母 | B20: =REPT("▮",MAX(1,ROUND((D9-C9)/10,0)))&" ["&TEXT(C9,"0")&"—"&TEXT(D9,"0")&"]"
A21: FCFE股权现金流 — 基准 | B21: =REPT("▮",MAX(1,ROUND((D10-C10)/10,0)))&" ["&TEXT(C10,"0")&"—"&TEXT(D10,"0")&"]"
A23: 关键假设提示 | B23: WACC采用值与可比beta联动(Assumptions第十节); 三情景主模型切换见Assumptions情景开关; 校验状态见Checks页

Sheet Assumptions
A1: 中芯国际(00981.HK) — Assumptions 驱动总表
A2: 单位: 美元百万元(财报口径)(除标注外) | 蓝色=输入/假设, 绿色=外部数据, 黑色=公式 | 数据日期: 2026-08-17
A4: 一、全局与市场数据
A5: 情景开关 (1=熊/2=基准/3=牛) | B5: - | C5: 2 | H5: 三情景总开关, 驱动Revenue_Segments分部增速与毛利率、进而贯穿IS/BS/CF/DCF; 默认2=基准
A6: 估值基准日 / 行情数据日期 | C6: 2026-08-17 | H6: 现价与可比公司市值均为2026-08-17收盘(腾讯行情); DCF采用年中折现(见DCF页)
A7: 现价 | B7: 元/股 | C7: 9.6218 | H7: 2026-08-17腾讯行情港元现价75.05 / fx7.8=9.6218美元
A8: 总股本 | B8: 百万股 | C8: 8561.1 | H8: 总市值6425.1亿港元/港元现价(腾讯行情 2026-08-17); 港股总市值=全部股本×港元价, 与A+H实际口径有差异
A9: 总市值 | B9: 百万 | C9: =C7*C8 | H9: ＝现价×总股本, 约824亿元, 与行情软件一致
A11: 二、市场一致预期与最新财报 (外部数据, 绿色)
A12: 一致预期2026E营收 | B12: 百万 | C12: 10833.2 | H12: 自动推导(无一致预期输入): 最近年报收入×(1+YoY+16.2%)退坡; 建议手工填入
A13: 一致预期2026E归母净利 | B13: 百万 | C13: 795.8 | H13: 自动推导(无一致预期输入): 收入×最近年报净利率7.3%; 建议手工填入
A14: 一致预期2027E营收 | B14: 百万 | C14: 10456.6 | H14: 自动推导(无一致预期输入): 最近年报收入×(1+YoY+16.2%)退坡; 建议手工填入
A15: 一致预期2027E归母净利 | B15: 百万 | C15: 768.1 | H15: 自动推导(无一致预期输入): 收入×最近年报净利率7.3%; 建议手工填入
A16: 一致预期2028E营收 | B16: 百万 | C16: 10155.3 | H16: 自动推导(无一致预期输入): 最近年报收入×(1+YoY+16.2%)退坡; 建议手工填入
A17: 一致预期2028E归母净利 | B17: 百万 | C17: 746 | H17: 自动推导(无一致预期输入): 收入×最近年报净利率7.3%; 建议手工填入
A19: 三、分部收入驱动 — 量/价增速 (蓝色输入, 2026E-2030E)
A20: 年份 | C20: 2026E | D20: 2027E | E20: 2028E | F20: 2029E | G20: 2030E | H20: 假设依据 / 来源
A21: 整体 收入增速 | B21: % | C21: 0.1615 | D21: 0.1211 | E21: 0.0888 | F21: 0.0646 | G21: 0.0485 | H21: 自动推导: 最近年报总收入YoY=+16.2%(截断[-15%,35%])逐年退坡×1/.75/.55/.40/.30; 建议按研究修正
A23: 四、分部毛利率 (蓝色输入)
A24: 整体 毛利率 | B24: % | C24: 0.2098 | D24: 0.2098 | E24: 0.2098 | F24: 0.2098 | G24: 0.2098 | H24: 自动推导: 最近年报综合毛利率21.0%持平; 建议按研究修正
A26: 五、费用率 / 其他损益 / 税率
A27: 税金及附加率 | B27: % | C27: 0 | D27: 0 | E27: 0 | F27: 0 | G27: 0 | H27: 自动推导: 最近年报税金及附加率0.00%持平
A28: 销售费用率 | B28: % | C28: 0.0046 | D28: 0.0046 | E28: 0.0046 | F28: 0.0046 | G28: 0.0046 | H28: 自动推导: 最近年报销售费用率持平
A29: 管理费用率 | B29: % | C29: 0.0564 | D29: 0.0564 | E29: 0.0564 | F29: 0.0564 | G29: 0.0564 | H29: 自动推导: 最近年报管理费用率持平
A30: 研发费用率 | B30: % | C30: 0.0829 | D30: 0.0829 | E30: 0.0829 | F30: 0.0829 | G30: 0.0829 | H30: 自动推导: 最近年报研发费用率持平
A31: 其他经营损益 | B31: 百万 | C31: 471.2 | D31: 471.2 | E31: 471.2 | F31: 471.2 | G31: 471.2 | H31: 自动推导: 最近年报其他经营损益(轧差项)持平
A32: 营业外收支净额 | B32: 百万 | C32: -36.7 | D32: -36.7 | E32: -36.7 | F32: -36.7 | G32: -36.7 | H32: 自动推导: 最近年报营业外收支净额持平
A33: 有效税率 | B33: % | C33: 0.1096 | D33: 0.1096 | E33: 0.1096 | F33: 0.1096 | G33: 0.1096 | H33: 自动推导: 最近年报有效税率11.0%(截断[5%,25%])持平
A34: 其他及财务费用率合计(情景页用) | B34: % | C34: -0.0027 | H34: 自动推导: 最近年报财务费用率, 供Scenarios页简化净利率计算
A36: 六、营运资本天数
A37: DSO 应收(票据+账款)天数 | B37: 天 | C37: 56 | D37: 56 | E37: 56 | F37: 56 | G37: 56 | H37: 自动推导: 最近年报DSO 56天持平
A38: DIO 存货天数 | B38: 天 | C38: 180 | D38: 180 | E38: 180 | F38: 180 | G38: 180 | H38: 自动推导: 最近年报DIO 180天持平
A39: DPO 应付(票据+账款)天数 | B39: 天 | C39: 147 | D39: 147 | E39: 147 | F39: 147 | G39: 147 | H39: 自动推导: 最近年报DPO 147天持平
A40: 预付款项/收入 | B40: % | C40: 0.0072 | D40: 0.0072 | E40: 0.0072 | F40: 0.0072 | G40: 0.0072 | H40: 自动推导: 最近年报预付/收入持平
A41: 应付职工薪酬/收入 | B41: % | C41: 0 | D41: 0 | E41: 0 | F41: 0 | G41: 0 | H41: 自动推导: 最近年报应付职工薪酬/收入持平
A42: 应交税费/收入 | B42: % | C42: 0.0036 | D42: 0.0036 | E42: 0.0036 | F42: 0.0036 | G42: 0.0036 | H42: 自动推导: 最近年报应交税费/收入持平
A44: 七、资本开支与折旧摊销 (PP&E页驱动)
A45: Capex占收入比 | B45: % | C45: 0.35 | D45: 0.2975 | E45: 0.245 | F45: 0.21 | G45: 0.175 | H45: 自动推导: 最近年报Capex/收入90.1%(上限35%)逐年退坡×1/.85/.70/.60/.50
A46: 在建工程转固率 | B46: % | C46: 0.75 | H46: 通用默认: 当年转固=(期初在建+当年Capex)×75%
A47: 固定资产折旧率(期初净值) | B47: % | C47: 0.12 | H47: 通用默认: 固定资产净值口径12%
...

Sheet Revenue_Segments
A1: 中芯国际 — Revenue_Segments 分业务收入拆解 (量×价驱动)
A2: 单位: 美元百万元(财报口径) | 历史收入=产品占比×总收入; 预测收入=上年×(1+量增速)×(1+价增速), 增速引用Assumptions并受情景开关调整
A3: 项目 | B3: 2023A | C3: 2024A | D3: 2025A | E3: 2026E | F3: 2027E | G3: 2028E | H3: 2029E | I3: 2030E | J3: 备注 / 来源
A4: 营业收入合计(历史实际) | B4: 6321.6 | C4: 8029.9 | D4: 9326.8 | J4: 东财F10利润表: 2023-2025实际营收
A5: 整体业务(单段简化)
A6: 收入 | B6: =B7*B$4 | C6: =C7*C$4 | D6: =D7*D$4 | E6: =D6*(1+E8) | F6: =E6*(1+F8) | G6: =F6*(1+G8) | H6: =G6*(1+H8) | I6: =H6*(1+I8)
A7: 收入占比 | B7: 1 | C7: 1 | D7: 1 | E7: =E6/E13 | F7: =F6/F13 | G7: =G6/G13 | H7: =H6/H13 | I7: =I6/I13 | J7: 港股无东财主营构成(按产品)披露, 单段=总收入100%
A8: 收入增速 | B8: — | C8: — | D8: — | E8: =(Assumptions!C$21+CHOOSE(Assumptions!$C$5,Assumptions!$C$87,Assumptions!$C$88,Assumptions!$C$89)) | F8: =(Assumptions!D$21+CHOOSE(Assumptions!$C$5,Assumptions!$C$87,Assumptions!$C$88,Assumptions!$C$89)) | G8: =(Assumptions!E$21+CHOOSE(Assumptions!$C$5,Assumptions!$C$87,Assumptions!$C$88,Assumptions!$C$89)) | H8: =(Assumptions!F$21+CHOOSE(Assumptions!$C$5,Assumptions!$C$87,Assumptions!$C$88,Assumptions!$C$89)) | I8: =(Assumptions!G$21+CHOOSE(Assumptions!$C$5,Assumptions!$C$87,Assumptions!$C$88,Assumptions!$C$89)) | J8: ＝Assumptions基础增速+CHOOSE(情景开关,熊,基,牛)
A9: 毛利率 | B9: 0.1926 | C9: 0.1803 | D9: 0.2098 | E9: =(Assumptions!C$24+CHOOSE(Assumptions!$C$5,Assumptions!$D$87,Assumptions!$D$88,Assumptions!$D$89)) | F9: =(Assumptions!D$24+CHOOSE(Assumptions!$C$5,Assumptions!$D$87,Assumptions!$D$88,Assumptions!$D$89)) | G9: =(Assumptions!E$24+CHOOSE(Assumptions!$C$5,Assumptions!$D$87,Assumptions!$D$88,Assumptions!$D$89)) | H9: =(Assumptions!F$24+CHOOSE(Assumptions!$C$5,Assumptions!$D$87,Assumptions!$D$88,Assumptions!$D$89)) | I9: =(Assumptions!G$24+CHOOSE(Assumptions!$C$5,Assumptions!$D$87,Assumptions!$D$88,Assumptions!$D$89)) | J9: 历史: 主营构成分产品毛利率; 预测: Assumptions+情景调整
A10: 毛利 | B10: =B6*B9 | C10: =C6*C9 | D10: =D6*D9 | E10: =E6*E9 | F10: =F6*F9 | G10: =G6*G9 | H10: =H6*H9 | I10: =I6*I9
A11: 逻辑: 港股单段简化(东财HKF10无主营构成披露); 历史毛利率=1-销售成本/营业额(IFRS)
A12: 合计 (自动汇总进IS)
A13: 营业收入合计 | B13: =B6 | C13: =C6 | D13: =D6 | E13: =E6 | F13: =F6 | G13: =G6 | H13: =H6 | I13: =I6
A14: 毛利合计 | B14: =B10 | C14: =C10 | D14: =D10 | E14: =E10 | F14: =F10 | G14: =G10 | H14: =H10 | I14: =I10
A15: 综合毛利率 | B15: =B14/B13 | C15: =C14/C13 | D15: =D14/D13 | E15: =E14/E13 | F15: =F14/F13 | G15: =G14/G13 | H15: =H14/H13 | I15: =I14/I13
A16: 收入YoY | C16: =C13/B13-1 | D16: =D13/C13-1 | E16: =E13/D13-1 | F16: =F13/E13-1 | G16: =G13/F13-1 | H16: =H13/G13-1 | I16: =I13/H13-1
A18: 基准情形演算 (仅引用Assumptions基础值, 不受情景开关影响, 供Scenarios页引用)
A19: 基准收入 — seg1 | D19: =D6 | E19: =D19*(1+Assumptions!C$21) | F19: =E19*(1+Assumptions!D$21) | G19: =F19*(1+Assumptions!E$21) | H19: =G19*(1+Assumptions!F$21) | I19: =H19*(1+Assumptions!G$21)
A20: 基准合计收入 | D20: =D6 | E20: =E19 | F20: =F19 | G20: =G19 | H20: =H19 | I20: =I19
A21: 基准收入增速 | E21: =E20/D20-1 | F21: =F20/E20-1 | G21: =G20/F20-1 | H21: =H20/G20-1 | I21: =I20/H20-1
A22: 基准综合毛利率 | E22: =(E19*Assumptions!C$24)/E20 | F22: =(F19*Assumptions!D$24)/F20 | G22: =(G19*Assumptions!E$24)/G20 | H22: =(H19*Assumptions!F$24)/H20 | I22: =(I19*Assumptions!G$24)/I20

Sheet IS
A1: 中芯国际 — IS 利润表 (2023A-2030E)
A2: 单位: 美元百万元(财报口径) | 收入/成本引用Revenue_Segments; 费用率/税率引用Assumptions; 财务费用引用FIN(平均余额计息, FIN页迭代展开第4轮输出)
A3: 项目 | B3: 2023A | C3: 2024A | D3: 2025A | E3: 2026E | F3: 2027E | G3: 2028E | H3: 2029E | I3: 2030E | J3: 备注 / 来源
A4: 营业收入 | B4: =Revenue_Segments!B13 | C4: =Revenue_Segments!C13 | D4: =Revenue_Segments!D13 | E4: =Revenue_Segments!E13 | F4: =Revenue_Segments!F13 | G4: =Revenue_Segments!G13 | H4: =Revenue_Segments!H13 | I4: =Revenue_Segments!I13 | J4: ＝Revenue_Segments分部合计; 历史: 东财F10(63.2/80.3/93.3亿)
A5: 收入YoY | C5: =C4/B4-1 | D5: =D4/C4-1 | E5: =E4/D4-1 | F5: =F4/E4-1 | G5: =G4/F4-1 | H5: =H4/G4-1 | I5: =I4/H4-1 | J5: 历史: 2024A +27.0% / 2025A +16.2%
A6: 营业成本 | B6: 5103.8 | C6: 6582 | D6: 7370.2 | E6: =E4-Revenue_Segments!E14 | F6: =F4-Revenue_Segments!F14 | G6: =G4-Revenue_Segments!G14 | H6: =H4-Revenue_Segments!H14 | I6: =I4-Revenue_Segments!I14 | J6: 历史: 东财F10实际值; 预测=收入-分部毛利合计(占比四舍五入, 历史分部毛利与总额存微小口径差)
A7: 毛利 | B7: =B4-B6 | C7: =C4-C6 | D7: =D4-D6 | E7: =E4-E6 | F7: =F4-F6 | G7: =G4-G6 | H7: =H4-H6 | I7: =I4-I6
A8: 毛利率 | B8: =B7/B4 | C8: =C7/C4 | D8: =D7/D4 | E8: =E7/E4 | F8: =F7/F4 | G8: =G7/G4 | H8: =H7/H4 | I8: =I7/I4 | J8: 2023A 19.3%→2025A 21.0%; 预测由分部毛利率加权
A9: 税金及附加 | B9: 0 | C9: 0 | D9: 0 | E9: =E4*Assumptions!C$27 | F9: =F4*Assumptions!D$27 | G9: =G4*Assumptions!E$27 | H9: =H4*Assumptions!F$27 | I9: =I4*Assumptions!G$27 | J9: 预测=收入×0.00%
A10: 销售费用 | B10: 36.2 | C10: 39.8 | D10: 43 | E10: =E4*Assumptions!C$28 | F10: =F4*Assumptions!D$28 | G10: =G4*Assumptions!E$28 | H10: =H4*Assumptions!F$28 | I10: =I4*Assumptions!G$28 | J10: 预测=收入×0.46%
A11: 管理费用 | B11: 482.3 | C11: 580 | D11: 526.2 | E11: =E4*Assumptions!C$29 | F11: =F4*Assumptions!D$29 | G11: =G4*Assumptions!E$29 | H11: =H4*Assumptions!F$29 | I11: =I4*Assumptions!G$29 | J11: 预测=收入×5.64%
A12: 研发费用 | B12: 707.3 | C12: 765.3 | D12: 773.6 | E12: =E4*Assumptions!C$30 | F12: =F4*Assumptions!D$30 | G12: =G4*Assumptions!E$30 | H12: =H4*Assumptions!F$30 | I12: =I4*Assumptions!G$30 | J12: 预测=收入×8.29%
A13: 财务费用 | B13: -527.2 | C13: -248.9 | D13: -25 | E13: =FIN!E67 | F13: =FIN!F67 | G13: =FIN!G67 | H13: =FIN!H67 | I13: =FIN!I67 | J13: 预测=FIN净财务费用(平均余额计息, 第4轮迭代展开输出)
A14: 其他经营损益(投资/公允/减值等) | B14: -161.5 | C14: 162.1 | D14: 471.2 | E14: =Assumptions!C$31 | F14: =Assumptions!D$31 | G14: =Assumptions!E$31 | H14: =Assumptions!F$31 | I14: =Assumptions!G$31 | J14: 历史为轧差项; 预测取471百万
A15: 营业利润 | B15: =B7-B9-B10-B11-B12-B13+B14 | C15: =C7-C9-C10-C11-C12-C13+C14 | D15: =D7-D9-D10-D11-D12-D13+D14 | E15: =E7-E9-E10-E11-E12-E13+E14 | F15: =F7-F9-F10-F11-F12-F13+F14 | G15: =G7-G9-G10-G11-G12-G13+G14 | H15: =H7-H9-H10-H11-H12-H13+H14 | I15: =I7-I9-I10-I11-I12-I13+I14
A16: 营业外收支净额 | B16: 829.7 | C16: 385.7 | D16: -36.7 | E16: =Assumptions!C$32 | F16: =Assumptions!D$32 | G16: =Assumptions!E$32 | H16: =Assumptions!F$32 | I16: =Assumptions!G$32 | J16: 2025A -36.7百万
A17: 利润总额 | B17: =B15+B16 | C17: =C15+C16 | D17: =D15+D16 | E17: =E15+E16 | F17: =F15+F16 | G17: =G15+G16 | H17: =H15+H16 | I17: =I15+I16
A18: 所得税 | B18: 62.5 | C18: 129.6 | D18: 84.3 | E18: =E17*Assumptions!C$33 | F18: =F17*Assumptions!D$33 | G18: =G17*Assumptions!E$33 | H18: =H17*Assumptions!F$33 | I18: =I17*Assumptions!G$33 | J18: 预测=利润总额×11.0%
A19: 净利润 | B19: =B17-B18 | C19: =C17-C18 | D19: =D17-D18 | E19: =E17-E18 | F19: =F17-F18 | G19: =G17-G18 | H19: =H17-H18 | I19: =I17-I18
A20: 归母净利润 | B20: =B19 | C20: =C19 | D20: =D19 | E20: =E19 | F20: =F19 | G20: =G19 | H20: =H19 | I20: =I19 | J20: 历史: 2023A 9.0亿/2024A 4.9亿/2025A 6.9亿
A21: 归母净利率 | B21: =B20/B4 | C21: =C20/C4 | D21: =D20/D4 | E21: =E20/E4 | F21: =F20/F4 | G21: =G20/G4 | H21: =H20/H4 | I21: =I20/I4 | J21: 2025A 7.3%
A22: EPS(元/股) | B22: =B20/Equity_Roll!$C$21 | C22: =C20/Equity_Roll!$C$21 | D22: =D20/Equity_Roll!$C$21 | E22: =E20/Equity_Roll!$C$21 | F22: =F20/Equity_Roll!$C$21 | G22: =G20/Equity_Roll!$C$21 | H22: =H20/Equity_Roll!$C$21 | I22: =I20/Equity_Roll!$C$21 | J22: ＝归母/稀释股数(Equity_Roll页, 现=85.61亿股)
A23: EBIT (利润总额+财务费用) | B23: =B17+B13 | C23: =C17+C13 | D23: =D17+D13 | E23: =E17+E13 | F23: =F17+F13 | G23: =G17+G13 | H23: =H17+H13 | I23: =I17+I13 | J23: 供DCF页FCFF计算

Sheet BS
A1: 中芯国际 — BS 资产负债表 (2023A-2030E)
A2: 单位: 美元百万元(财报口径) | 配平机制=FIN页revolver新增借款/现金sweep/理财承接(货币资金=最低现金); 配平差额检查行应恒=0
A3: 项目 | B3: 2023A | C3: 2024A | D3: 2025A | E3: 2026E | F3: 2027E | G3: 2028E | H3: 2029E | I3: 2030E | J3: 备注 / 来源
A4: 货币资金 | B4: 0 | C4: 6364.2 | D4: 5872.5 | E4: =FIN!E63 | F4: =FIN!F63 | G4: =FIN!G63 | H4: =FIN!H63 | I4: =FIN!I63 | J4: 预测=FIN期末现金(=最低现金); 历史: 东财F10
A5: 交易性金融资产 | B5: 0 | C5: 4479.2 | D5: 4531.5 | E5: =FIN!E61 | F5: =FIN!F61 | G5: =FIN!G61 | H5: =FIN!H61 | I5: =FIN!I61 | J5: 预测=FIN理财期末(sweep溢出承接); 历史: 东财F10
A6: 应收票据及应收账款 | B6: 0 | C6: 840.2 | D6: 1432.7 | E6: =Assumptions!C$37/365*IS!E4 | F6: =Assumptions!D$37/365*IS!F4 | G6: =Assumptions!E$37/365*IS!G4 | H6: =Assumptions!F$37/365*IS!H4 | I6: =Assumptions!G$37/365*IS!I4 | J6: 预测=DSO/365×收入
A7: 预付款项 | B7: 106.2 | C7: 56.4 | D7: 67.5 | E7: =IS!E4*Assumptions!C$40 | F7: =IS!F4*Assumptions!D$40 | G7: =IS!G4*Assumptions!E$40 | H7: =IS!H4*Assumptions!F$40 | I7: =IS!I4*Assumptions!G$40 | J7: 预测=收入×0.7%
A8: 其他应收款 | B8: 0 | C8: 0 | D8: 0 | E8: =D8 | F8: =E8 | G8: =F8 | H8: =G8 | I8: =H8 | J8: 预测持平
A9: 存货 | B9: 0 | C9: 2958.3 | D9: 3629.8 | E9: =Assumptions!C$38/365*IS!E6 | F9: =Assumptions!D$38/365*IS!F6 | G9: =Assumptions!E$38/365*IS!G6 | H9: =Assumptions!F$38/365*IS!H6 | I9: =Assumptions!G$38/365*IS!I6 | J9: 预测=DIO/365×营业成本
A10: 应收款项融资及其他流动资产 | B10: 13529 | C10: 85.4 | D10: 91.1 | E10: =D10 | F10: =E10 | G10: =F10 | H10: =G10 | I10: =H10 | J10: 含应收款项融资/其他流动资产, 历史为轧差, 预测持平
A11: 流动资产合计 | B11: =B4+B5+B6+B7+B8+B9+B10 | C11: =C4+C5+C6+C7+C8+C9+C10 | D11: =D4+D5+D6+D7+D8+D9+D10 | E11: =E4+E5+E6+E7+E8+E9+E10 | F11: =F4+F5+F6+F7+F8+F9+F10 | G11: =G4+G5+G6+G7+G8+G9+G10 | H11: =H4+H5+H6+H7+H8+H9+H10 | I11: =I4+I5+I6+I7+I8+I9+I10
A12: 固定资产及在建工程 | B12: 23945 | C12: 28092 | D12: 32557.8 | E12: =PPE!E18 | F12: =PPE!F18 | G12: =PPE!G18 | H12: =PPE!H18 | I12: =PPE!I18 | J12: 预测=PP&E页期末合计; 2025A固资325.6亿+在建0.0亿
A13: 使用权资产 | B13: 0 | C13: 0 | D13: 0 | E13: =D13 | F13: =E13 | G13: =F13 | H13: =G13 | I13: =H13 | J13: 预测持平
A14: 无形资产 | B14: 0 | C14: 24.3 | D14: 20.4 | E14: =Schedules!E23 | F14: =Schedules!F23 | G14: =Schedules!G23 | H14: =Schedules!H23 | I14: =Schedules!I23 | J14: 预测=期初-摊销(Schedules)
A15: 商誉 | B15: 0 | C15: 0 | D15: 0 | E15: =D15 | F15: =E15 | G15: =F15 | H15: =G15 | I15: =H15 | J15: 预测持平
A16: 长期待摊费用 | B16: 0 | C16: 0 | D16: 0 | E16: =D16 | F16: =E16 | G16: =F16 | H16: =G16 | I16: =H16 | J16: 预测持平
A17: 递延所得税资产 | B17: 0 | C17: 29.2 | D17: 35.2 | E17: =D17 | F17: =E17 | G17: =F17 | H17: =G17 | I17: =H17 | J17: 预测持平
A18: 其他权益工具投资 | B18: 0 | C18: 3747.1 | D18: 1532.3 | E18: =D18 | F18: =E18 | G18: =F18 | H18: =G18 | I18: =H18 | J18: 预测持平; 2025A末15.3亿已计入DCF的EV→Equity桥
A19: 其他非流动资产 | B19: -23945 | C19: 2484.9 | D19: 2500.6 | E19: =D19 | F19: =E19 | G19: =F19 | H19: =G19 | I19: =H19 | J19: 历史为轧差, 预测持平
A20: 非流动资产合计 | B20: =B12+B13+B14+B15+B16+B17+B18+B19 | C20: =C12+C13+C14+C15+C16+C17+C18+C19 | D20: =D12+D13+D14+D15+D16+D17+D18+D19 | E20: =E12+E13+E14+E15+E16+E17+E18+E19 | F20: =F12+F13+F14+F15+F16+F17+F18+F19 | G20: =G12+G13+G14+G15+G16+G17+G18+G19 | H20: =H12+H13+H14+H15+H16+H17+H18+H19 | I20: =I12+I13+I14+I15+I16+I17+I18+I19
A21: 资产总计 | B21: =B11+B20 | C21: =C11+C20 | D21: =D11+D20 | E21: =E11+E20 | F21: =F11+F20 | G21: =G11+G20 | H21: =H11+H20 | I21: =I11+I20 | J21: 2025A 522.7亿
A22: 短期借款 | B22: 0 | C22: 2926.3 | D22: 2593.1 | E22: =FIN!E24 | F22: =FIN!F24 | G22: =FIN!G24 | H22: =FIN!H24 | I22: =FIN!I24 | J22: 预测=FIN revolver期末(缺口新增-sweep偿还)
A23: 应付票据及应付账款 | B23: 3727.9 | C23: 3280.4 | D23: 2966 | E23: =Assumptions!C$39/365*IS!E6 | F23: =Assumptions!D$39/365*IS!F6 | G23: =Assumptions!E$39/365*IS!G6 | H23: =Assumptions!F$39/365*IS!H6 | I23: =Assumptions!G$39/365*IS!I6 | J23: 预测=DPO/365×营业成本
A24: 合同负债 | B24: 0 | C24: 1547.9 | D24: 1009.1 | E24: =D24 | F24: =E24 | G24: =F24 | H24: =G24 | I24: =H24 | J24: 预测持平
A25: 应付职工薪酬 | B25: 0 | C25: 0 | D25: 0 | E25: =IS!E4*Assumptions!C$41 | F25: =IS!F4*Assumptions!D$41 | G25: =IS!G4*Assumptions!E$41 | H25: =IS!H4*Assumptions!F$41 | I25: =IS!I4*Assumptions!G$41 | J25: 预测=收入×0.0%
A26: 应交税费 | B26: 0 | C26: 84.8 | D26: 33.5 | E26: =IS!E4*Assumptions!C$42 | F26: =IS!F4*Assumptions!D$42 | G26: =IS!G4*Assumptions!E$42 | H26: =IS!H4*Assumptions!F$42 | I26: =IS!I4*Assumptions!G$42 | J26: 预测=收入×0.4%
A27: 其他应付款 | B27: 0 | C27: 0 | D27: 0 | E27: =D27 | F27: =E27 | G27: =F27 | H27: =G27 | I27: =H27 | J27: 预测持平
A28: 一年内到期的非流动负债 | B28: 0 | C28: 18.5 | D28: 7.5 | E28: =FIN!E32 | F28: =FIN!F32 | G28: =FIN!G32 | H28: =FIN!H32 | I28: =FIN!I32 | J28: 预测=FIN期末(计划还款摊还)
A29: 其他流动负债 | B29: 3873.7 | C29: 901.8 | D29: 207.9 | E29: =D29 | F29: =E29 | G29: =F29 | H29: =G29 | I29: =H29 | J29: 历史为轧差, 预测持平
A30: 流动负债合计 | B30: =B22+B23+B24+B25+B26+B27+B28+B29 | C30: =C22+C23+C24+C25+C26+C27+C28+C29 | D30: =D22+D23+D24+D25+D26+D27+D28+D29 | E30: =E22+E23+E24+E25+E26+E27+E28+E29 | F30: =F22+F23+F24+F25+F26+F27+F28+F29 | G30: =G22+G23+G24+G25+G26+G27+G28+G29 | H30: =H22+H23+H24+H25+H26+H27+H28+H29 | I30: =I22+I23+I24+I25+I26+I27+I28+I29
A31: 长期借款 | B31: 0 | C31: 8038.1 | D31: 9994.8 | E31: =FIN!E42 | F31: =FIN!F42 | G31: =FIN!G42 | H31: =FIN!H42 | I31: =FIN!I42 | J31: 预测=FIN期末(计划还款+sweep)
A32: 租赁负债 | B32: 26.3 | C32: 7.8 | D32: 0.8 | E32: =FIN!E50 | F32: =FIN!F50 | G32: =FIN!G50 | H32: =FIN!H50 | I32: =FIN!I50 | J32: 预测=FIN期末(计划还款摊还)
A33: 其他非流动负债 | B33: -26.3 | C33: 486 | D33: 438.1 | E33: =D33 | F33: =E33 | G33: =F33 | H33: =G33 | I33: =H33 | J33: 含递延收益/递延所得税负债, 历史轧差, 预测持平
A34: 非流动负债合计 | B34: =B31+B32+B33 | C34: =C31+C32+C33 | D34: =D31+D32+D33 | E34: =E31+E32+E33 | F34: =F31+F32+F33 | G34: =G31+G32+G33 | H34: =H31+H32+H33 | I34: =I31+I32+I33
A35: 负债合计 | B35: =B30+B34 | C35: =C30+C34 | D35: =D30+D34 | E35: =E30+E34 | F35: =F30+F34 | G35: =G30+G34 | H35: =H30+H34 | I35: =I30+I34
A36: 股本 | B36: 0 | C36: 31.9 | D36: 32 | E36: =Equity_Roll!E5 | F36: =Equity_Roll!F5 | G36: =Equity_Roll!G5 | H36: =Equity_Roll!H5 | I36: =Equity_Roll!I5 | J36: 预测=Equity_Roll(持平)
A37: 资本公积 | B37: 0 | C37: 14266.4 | D37: 14394.8 | E37: =Equity_Roll!E6 | F37: =Equity_Roll!F6 | G37: =Equity_Roll!G6 | H37: =Equity_Roll!H6 | I37: =Equity_Roll!I6 | J37: 预测=Equity_Roll(持平)
A38: 减:库存股 | B38: 0 | C38: 0 | D38: 0 | E38: =Equity_Roll!E7 | F38: =Equity_Roll!F7 | G38: =Equity_Roll!G7 | H38: =Equity_Roll!H7 | I38: =Equity_Roll!I7 | J38: 预测=Equity_Roll(持平)
A39: 其他综合收益 | B39: 286.9 | C39: 142.5 | D39: 154.7 | E39: =Equity_Roll!E8 | F39: =Equity_Roll!F8 | G39: =Equity_Roll!G8 | H39: =Equity_Roll!H8 | I39: =Equity_Roll!I8 | J39: 预测=Equity_Roll(持平)
A40: 盈余公积 | B40: 0 | C40: 0 | D40: 0 | E40: =Equity_Roll!E10 | F40: =Equity_Roll!F10 | G40: =Equity_Roll!G10 | H40: =Equity_Roll!H10 | I40: =Equity_Roll!I10 | J40: 预测=Equity_Roll(期初+归母×0%)
...

Sheet CF
A1: 中芯国际 — CF 现金流量表 (间接法, 2023A-2030E)
A2: 单位: 美元百万元(财报口径) | 利息支出经营加回、筹资列"偿付利息"; 投资含"理财净变动"; 期末货币资金=FIN期末现金=BS货币资金
A3: 项目 | B3: 2023A | C3: 2024A | D3: 2025A | E3: 2026E | F3: 2027E | G3: 2028E | H3: 2029E | I3: 2030E | J3: 备注 / 来源
A4: 归母净利润 | B4: 902.5 | C4: 492.7 | D4: 685.1 | E4: =IS!E20 | F4: =IS!F20 | G4: =IS!G20 | H4: =IS!H20 | I4: =IS!I20 | J4: ＝IS归母净利
A5: 加: 折旧与摊销(D&A) | B5: 18891.6 | C5: 3223.1 | D5: 3810 | E5: =PPE!E19 | F5: =PPE!F19 | G5: =PPE!G19 | H5: =PPE!H19 | I5: =PPE!I19 | J5: 历史=固定资产折旧+无形/长待摊摊销; 预测=PP&E页合计
A6: 加: 利息支出(重分类至筹资) | B6: — | C6: — | D6: — | E6: =FIN!E64 | F6: =FIN!F64 | G6: =FIN!G64 | H6: =FIN!H64 | I6: =FIN!I64 | J6: 利润表中利息属筹资活动, 经营现金流加回; 历史未拆(列—)
A7: 减: 营运资本变动(增加为负) | B7: — | C7: — | D7: — | E7: =-Schedules!E18 | F7: =-Schedules!F18 | G7: =-Schedules!G18 | H7: =-Schedules!H18 | I7: =-Schedules!I18 | J7: 预测=-ΔNWC(Schedules)
A8: 经营活动现金流量净额 | B8: 23785.8 | C8: 3175.6 | D8: 3194.3 | E8: =E4+E5+E6+E7 | F8: =F4+F5+F6+F7 | G8: =G4+G5+G6+G7 | H8: =H4+H5+H6+H7 | I8: =I4+I5+I6+I7 | J8: 历史为年报实际值(含利息, 口径与预测略有差异)
A9: 资本开支(购建长期资产) | B9: -54065.4 | C9: -7669.9 | D9: -8403.5 | E9: =-PPE!E14 | F9: =-PPE!F14 | G9: =-PPE!G14 | H9: =-PPE!H14 | I9: =-PPE!I14 | J9: 预测=-收入×Capex占比(PP&E页)
A10: 加: 处置固定资产回收(账面值) | B10: — | C10: — | D10: — | E10: =PPE!E9 | F10: =PPE!F9 | G10: =PPE!G9 | H10: =PPE!H9 | I10: =PPE!I9 | J10: 预测=PP&E页处置额(按账面值回收, 无损益); 历史含在投资净额内(列—)
A11: 理财净变动(交易性金融资产) | B11: — | C11: — | D11: — | E11: =-FIN!E62 | F11: =-FIN!F62 | G11: =-FIN!G62 | H11: =-FIN!H62 | I11: =-FIN!I62 | J11: ＝-FIN理财净变动(sweep溢出购买为流出); 历史含在投资净额内(列—)
A12: 投资活动现金流量净额 | B12: -43966.4 | C12: -4518.4 | D12: -6495.4 | E12: =E9+E10+E11 | F12: =F9+F10+F11 | G12: =G9+G10+G11 | H12: =H9+H10+H11 | I12: =I9+I10+I11 | J12: 历史为年报实际值; 预测=资本开支+处置回收+理财净变动
A13: 债务净变动(新增为正) | B13: — | C13: — | D13: — | E13: =FIN!E57 | F13: =FIN!F57 | G13: =FIN!G57 | H13: =FIN!H57 | I13: =FIN!I57 | J13: ＝FIN四档债务期末-期初(含revolver新增/sweep偿还)
A14: 偿付利息 | B14: — | C14: — | D14: — | E14: =-FIN!E64 | F14: =-FIN!F64 | G14: =-FIN!G64 | H14: =-FIN!H64 | I14: =-FIN!I64 | J14: 利息支出列筹资活动
A15: 股利支付 | B15: — | C15: — | D15: — | E15: =-Schedules!E26 | F15: =-Schedules!F26 | G15: =-Schedules!G26 | H15: =-Schedules!H26 | I15: =-Schedules!I26 | J15: ＝-上年归母×30%
A16: 筹资活动现金流量净额 | B16: 17468.3 | C16: 1608.3 | D16: 2676.5 | E16: =E13+E14+E15 | F16: =F13+F14+F15 | G16: =G13+G14+G15 | H16: =H13+H14+H15 | I16: =I13+I14+I15 | J16: 历史为年报实际值; 预测=债务净变动-利息-股利
A17: 货币资金净增加额 | B17: — | C17: — | D17: — | E17: =E8+E12+E16 | F17: =F8+F12+F16 | G17: =G8+G12+G16 | H17: =H8+H12+H16 | I17: =I8+I12+I16
A18: 期初货币资金 | B18: — | C18: — | D18: — | E18: =BS!D4 | F18: =E19 | G18: =F19 | H18: =G19 | I18: =H19 | J18: 2026期初=2025A末货币资金
A19: 期末货币资金(=BS货币资金) | B19: 44019.4 | C19: 6364.2 | D19: 5872.5 | E19: =E18+E17 | F19: =F18+F17 | G19: =G18+G17 | H19: =H18+H17 | I19: =I18+I17 | J19: 历史=BS货币资金; 预测=期初+净增加=FIN期末现金(最低现金)

Sheet Schedules
A1: 中芯国际 — Schedules 营运资本 / 无形资产 / 股利
A2: 单位: 美元百万元(财报口径) | PP&E见PP&E页, 债务与利息见FIN页; 预测行全公式
A3: 项目 | B3: 2023A | C3: 2024A | D3: 2025A | E3: 2026E | F3: 2027E | G3: 2028E | H3: 2029E | I3: 2030E | J3: 备注
A5: 一、营运资本 (NWC)
A6: 应收票据及应收账款 | B6: =BS!B6 | C6: =BS!C6 | D6: =BS!D6 | E6: =BS!E6 | F6: =BS!F6 | G6: =BS!G6 | H6: =BS!H6 | I6: =BS!I6 | J6: ＝BS, 预测=DSO/365×收入
A7: 预付款项 | B7: =BS!B7 | C7: =BS!C7 | D7: =BS!D7 | E7: =BS!E7 | F7: =BS!F7 | G7: =BS!G7 | H7: =BS!H7 | I7: =BS!I7 | J7: ＝BS, 预测=收入×预付率
A8: 其他应收款 | B8: =BS!B8 | C8: =BS!C8 | D8: =BS!D8 | E8: =BS!E8 | F8: =BS!F8 | G8: =BS!G8 | H8: =BS!H8 | I8: =BS!I8 | J8: ＝BS, 预测持平
A9: 存货 | B9: =BS!B9 | C9: =BS!C9 | D9: =BS!D9 | E9: =BS!E9 | F9: =BS!F9 | G9: =BS!G9 | H9: =BS!H9 | I9: =BS!I9 | J9: ＝BS, 预测=DIO/365×营业成本
A10: 经营性流动资产小计 | B10: =SUM(B6:B9) | C10: =SUM(C6:C9) | D10: =SUM(D6:D9) | E10: =SUM(E6:E9) | F10: =SUM(F6:F9) | G10: =SUM(G6:G9) | H10: =SUM(H6:H9) | I10: =SUM(I6:I9)
A11: 应付票据及应付账款 | B11: =BS!B23 | C11: =BS!C23 | D11: =BS!D23 | E11: =BS!E23 | F11: =BS!F23 | G11: =BS!G23 | H11: =BS!H23 | I11: =BS!I23 | J11: ＝BS, 预测=DPO/365×营业成本
A12: 合同负债 | B12: =BS!B24 | C12: =BS!C24 | D12: =BS!D24 | E12: =BS!E24 | F12: =BS!F24 | G12: =BS!G24 | H12: =BS!H24 | I12: =BS!I24 | J12: ＝BS, 持平
A13: 应付职工薪酬 | B13: =BS!B25 | C13: =BS!C25 | D13: =BS!D25 | E13: =BS!E25 | F13: =BS!F25 | G13: =BS!G25 | H13: =BS!H25 | I13: =BS!I25 | J13: ＝BS, 预测=收入×比率
A14: 应交税费 | B14: =BS!B26 | C14: =BS!C26 | D14: =BS!D26 | E14: =BS!E26 | F14: =BS!F26 | G14: =BS!G26 | H14: =BS!H26 | I14: =BS!I26 | J14: ＝BS, 预测=收入×比率
A15: 其他应付款 | B15: =BS!B27 | C15: =BS!C27 | D15: =BS!D27 | E15: =BS!E27 | F15: =BS!F27 | G15: =BS!G27 | H15: =BS!H27 | I15: =BS!I27 | J15: ＝BS, 持平
A16: 经营性流动负债小计 | B16: =SUM(B11:B15) | C16: =SUM(C11:C15) | D16: =SUM(D11:D15) | E16: =SUM(E11:E15) | F16: =SUM(F11:F15) | G16: =SUM(G11:G15) | H16: =SUM(H11:H15) | I16: =SUM(I11:I15)
A17: 净营运资本 NWC | B17: =B10-B16 | C17: =C10-C16 | D17: =D10-D16 | E17: =E10-E16 | F17: =F10-F16 | G17: =G10-G16 | H17: =H10-H16 | I17: =I10-I16 | J17: ＝经营性流动资产-经营性流动负债
A18: ΔNWC (增加为正) | E18: =E17-D17 | F18: =F17-E17 | G18: =G17-F17 | H18: =H17-G17 | I18: =I17-H17 | J18: CF中扣减项
A20: 二、无形资产摊销
A21: 期初无形资产 | E21: =BS!D14 | F21: =E23 | G21: =F23 | H21: =G23 | I21: =H23 | J21: 2026期初=2025A期末
A22: 无形资产摊销 | E22: =E21*Assumptions!$C$50 | F22: =F21*Assumptions!$C$50 | G22: =G21*Assumptions!$C$50 | H22: =H21*Assumptions!$C$50 | I22: =I21*Assumptions!$C$50 | J22: ＝期初×8%
A23: 期末无形资产 | E23: =E21-E22 | F23: =F21-F22 | G23: =G21-G22 | H23: =H21-H22 | I23: =I21-I22 | J23: ＝期初-摊销
A25: 三、股利
A26: 现金分红(当年支付) | E26: =IS!D20*Assumptions!C$53 | F26: =IS!E20*Assumptions!D$53 | G26: =IS!F20*Assumptions!E$53 | H26: =IS!G20*Assumptions!F$53 | I26: =IS!H20*Assumptions!G$53 | J26: ＝上年归母净利×支付率30%

Sheet PPE
A1: 中芯国际 — PP&E 固定资产/在建工程滚动
A2: 单位: 美元百万元(财报口径) | 固定资产与在建工程分行滚动: 期初+转固-折旧-处置 / 期初+Capex-转固; 隐含折旧率/年限校验行在底部
A3: 项目 | B3: 2023A | C3: 2024A | D3: 2025A | E3: 2026E | F3: 2027E | G3: 2028E | H3: 2029E | I3: 2030E | J3: 备注
A5: 一、固定资产 (净值口径)
A6: 期初固定资产净值 | E6: 32557.8 | F6: =E10 | G6: =F10 | H6: =G10 | I6: =H10 | J6: 2026期初=2025A固定资产325.6亿(绿色输入, 2025年报)
A7: 加: 在建工程转入 | E7: =(E13+E14)*Assumptions!$C$46 | F7: =(F13+F14)*Assumptions!$C$46 | G7: =(G13+G14)*Assumptions!$C$46 | H7: =(H13+H14)*Assumptions!$C$46 | I7: =(I13+I14)*Assumptions!$C$46 | J7: ＝(期初在建+当年Capex)×转固率75%
A8: 减: 固定资产折旧 | E8: =E6*Assumptions!$C$47+E7*Assumptions!$C$48 | F8: =F6*Assumptions!$C$47+F7*Assumptions!$C$48 | G8: =G6*Assumptions!$C$47+G7*Assumptions!$C$48 | H8: =H6*Assumptions!$C$47+H7*Assumptions!$C$48 | I8: =I6*Assumptions!$C$47+I7*Assumptions!$C$48 | J8: ＝期初净值×12%+当年转固×4%
A9: 减: 处置 | E9: =E6*Assumptions!$C$49 | F9: =F6*Assumptions!$C$49 | G9: =G6*Assumptions!$C$49 | H9: =H6*Assumptions!$C$49 | I9: =I6*Assumptions!$C$49 | J9: ＝期初净值×1%
A10: 期末固定资产净值 | E10: =E6+E7-E8-E9 | F10: =F6+F7-F8-F9 | G10: =G6+G7-G8-G9 | H10: =H6+H7-H8-H9 | I10: =I6+I7-I8-I9 | J10: ＝期初+转固-折旧-处置
A12: 二、在建工程
A13: 期初在建工程 | E13: 0 | F13: =E15 | G13: =F15 | H13: =G15 | I13: =H15 | J13: 2026期初=2025A在建工程0.0亿(绿色输入); 32557.8+0.0=32557.8与BS一致
A14: 加: 资本开支 Capex | E14: =IS!E4*Assumptions!C$45 | F14: =IS!F4*Assumptions!D$45 | G14: =IS!G4*Assumptions!E$45 | H14: =IS!H4*Assumptions!F$45 | I14: =IS!I4*Assumptions!G$45 | J14: ＝收入×Capex占收入比(Assumptions)
A15: 期末在建工程 | E15: =E13+E14-E7 | F15: =F13+F14-F7 | G15: =G13+G14-G7 | H15: =H13+H14-H7 | I15: =I13+I14-I7 | J15: ＝期初+Capex-转固
A17: 三、合计与校验
A18: 固定资产+在建工程 期末合计 | B18: =BS!B12 | C18: =BS!C12 | D18: =BS!D12 | E18: =E10+E15 | F18: =F10+F15 | G18: =G10+G15 | H18: =H10+H15 | I18: =I10+I15 | J18: ＝BS固定资产及在建工程; 2025A合计325.6亿
A19: D&A 合计 (折旧+无形摊销) | B19: =CF!B5 | C19: =CF!C5 | D19: =CF!D5 | E19: =E8+Schedules!E22 | F19: =F8+Schedules!F22 | G19: =G8+Schedules!G22 | H19: =H8+Schedules!H22 | I19: =I8+Schedules!I22 | J19: ＝折旧+Schedules无形摊销, 进CF与DCF
A20: 校验: 隐含折旧率(折旧/期初净值) | E20: =E8/E6 | F20: =F8/F6 | G20: =G8/G6 | H20: =H8/H6 | I20: =I8/I6 | J20: 信息行; 合理带宽8%-18%
A21: 校验: 隐含折旧年限(期初净值/折旧) | E21: =E6/E8 | F21: =F6/F8 | G21: =G6/G8 | H21: =H6/H8 | I21: =I6/I8 | J21: 信息行; 机器设备为主, 5-10年为合理带

Sheet FIN
A1: 中芯国际 — FIN 债务与融资调度 (迭代展开·无循环引用)
A2: 单位: 美元百万元(财报口径) | 瀑布: 期初现金+经营CF+投资CF(不含理财)+分红+计划还款+利息→缺口=revolver新增借款→超额现金sweep还短借/长借→溢出购理财; 利息=平均余额×利率的循环链在下方"四、迭代展开"区表内展开4轮, 末轮输出供全簿引用, 无需开启迭代计算
A3: 项目 | B3: 2023A | C3: 2024A | D3: 2025A | E3: 2026E | F3: 2027E | G3: 2028E | H3: 2029E | I3: 2030E | J3: 备注
A5: 一、资金瀑布 (融资需求与可动用现金)
A6: 期初货币资金 | E6: =D63 | F6: =E63 | G6: =F63 | H6: =G63 | I6: =H63 | J6: 2026=2025A末; 以后=上年期末
A7: 加: 经营活动现金流(不含利息) | E7: =CF!E8 | F7: =CF!F8 | G7: =CF!G8 | H7: =CF!H8 | I7: =CF!I8 | J7: ＝CF经营净额(利息已重分类至筹资)
A8: 加: 投资活动现金流(不含理财) | E8: =-PPE!E14+PPE!E9 | F8: =-PPE!F14+PPE!F9 | G8: =-PPE!G14+PPE!G9 | H8: =-PPE!H14+PPE!H9 | I8: =-PPE!I14+PPE!I9 | J8: ＝-Capex+处置回收(PP&E页)
A9: 减: 计划分红(负值) | E9: =-Schedules!E26 | F9: =-Schedules!F26 | G9: =-Schedules!G26 | H9: =-Schedules!H26 | I9: =-Schedules!I26 | J9: ＝-上年归母×30% (Schedules)
A10: 减: 偿付利息(负值) | E10: =-E64 | F10: =-F64 | G10: =-G64 | H10: =-H64 | I10: =-I64 | J10: ＝-本页利息支出合计(=第4轮迭代展开输出)
A11: 减: 实际还款合计(负值) | E11: =-(E20+E31+E39+E49) | F11: =-(F20+F31+F39+F49) | G11: =-(G20+G31+G39+G49) | H11: =-(H20+H31+H39+H49) | I11: =-(I20+I31+I39+I49) | J11: ＝四档实际还款加总(实际还款=MIN(计划还款,期初余额))
A12: 融资前现金结余 | E12: =E6+E7+E8+E9+E10+E11 | F12: =F6+F7+F8+F9+F10+F11 | G12: =G6+G7+G8+G9+G10+G11 | H12: =H6+H7+H8+H9+H10+H11 | I12: =I6+I7+I8+I9+I10+I11 | J12: ＝期初+经营+投资+分红+利息+还款
A13: 最低现金 | E13: =IS!E4*Assumptions!$C$57 | F13: =IS!F4*Assumptions!$C$57 | G13: =IS!G4*Assumptions!$C$57 | H13: =IS!H4*Assumptions!$C$57 | I13: =IS!I4*Assumptions!$C$57 | J13: ＝收入×60% (Assumptions)
A14: 资金缺口→新增借款(revolver) | E14: =MAX(0,E13-E12) | F14: =MAX(0,F13-F12) | G14: =MAX(0,G13-G12) | H14: =MAX(0,H13-H12) | I14: =MAX(0,I13-I12) | J14: ＝MAX(0, 最低现金-融资前结余)
A15: 可动用现金(还债+购理财) | E15: =MAX(0,E12+E14-E13) | F15: =MAX(0,F12+F14-F13) | G15: =MAX(0,G12+G14-G13) | H15: =MAX(0,H12+H14-H13) | I15: =MAX(0,I12+I14-I13) | J15: ＝MAX(0, 融资前结余+新增借款-最低现金)
A17: · 短期借款 (revolver: 新增借款入口, sweep第一顺位)
A18: 期初余额 | E18: =D24 | F18: =E24 | G18: =F24 | H18: =G24 | I18: =H24 | J18: 上年期末
A19: 计划还款(输入) | E19: =Assumptions!C$58 | F19: =Assumptions!D$58 | G19: =Assumptions!E$58 | H19: =Assumptions!F$58 | I19: =Assumptions!G$58 | J19: ＝Assumptions rep_st
A20: 实际还款(≤期初) | E20: =MIN(E19,E18) | F20: =MIN(F19,F18) | G20: =MIN(G19,G18) | H20: =MIN(H19,H18) | I20: =MIN(I19,I18) | J20: ＝MIN(计划还款, 期初余额); 防止债务清零后仍按计划额扣现金
A21: 新增借款 | E21: =E14 | F21: =F14 | G21: =G14 | H21: =H14 | I21: =I14 | J21: ＝资金缺口(全部经revolver融入)
A22: sweep前未偿余额 | E22: =E18-E20+E21 | F22: =F18-F20+F21 | G22: =G18-G20+G21 | H22: =H18-H20+H21 | I22: =I18-I20+I21 | J22: ＝期初-实际还款+新增
A23: 现金sweep偿还 | E23: =MIN(E15,E22) | F23: =MIN(F15,F22) | G23: =MIN(G15,G22) | H23: =MIN(H15,H22) | I23: =MIN(I15,I22) | J23: ＝MIN(可动用现金余额, sweep前未偿)
A24: 期末余额 | D24: =BS!D22 | E24: =E22-E23 | F24: =F22-F23 | G24: =G22-G23 | H24: =H22-H23 | I24: =I22-I23 | J24: ＝sweep前未偿-sweep
A25: 平均余额 | E25: =(E18+E24)/2 | F25: =(F18+F24)/2 | G25: =(G18+G24)/2 | H25: =(H18+H24)/2 | I25: =(I18+I24)/2 | J25: ＝(期初+期末)/2
A26: 利息支出 | E26: =E25*Assumptions!$C$62 | F26: =F25*Assumptions!$C$62 | G26: =G25*Assumptions!$C$62 | H26: =H25*Assumptions!$C$62 | I26: =I25*Assumptions!$C$62 | J26: ＝平均余额×利率(按期末余额重算的隐含值; 与采用值(第4轮迭代输出)之差见下方残差行)
A28: · 一年内到期的非流动负债 (仅计划还款)
A29: 期初余额 | E29: =D32 | F29: =E32 | G29: =F32 | H29: =G32 | I29: =H32 | J29: 上年期末
A30: 计划还款(输入) | E30: =Assumptions!C$59 | F30: =Assumptions!D$59 | G30: =Assumptions!E$59 | H30: =Assumptions!F$59 | I30: =Assumptions!G$59 | J30: ＝Assumptions rep_cur
A31: 实际还款(≤期初) | E31: =MIN(E30,E29) | F31: =MIN(F30,F29) | G31: =MIN(G30,G29) | H31: =MIN(H30,H29) | I31: =MIN(I30,I29) | J31: ＝MIN(计划还款, 期初余额); 防止债务清零后仍按计划额扣现金
A32: 期末余额 | D32: =BS!D28 | E32: =E29-E31 | F32: =F29-F31 | G32: =G29-G31 | H32: =H29-H31 | I32: =I29-I31 | J32: ＝期初-实际还款
A33: 平均余额 | E33: =(E29+E32)/2 | F33: =(F29+F32)/2 | G33: =(G29+G32)/2 | H33: =(H29+H32)/2 | I33: =(I29+I32)/2 | J33: ＝(期初+期末)/2
A34: 利息支出 | E34: =E33*Assumptions!$C$63 | F34: =F33*Assumptions!$C$63 | G34: =G33*Assumptions!$C$63 | H34: =H33*Assumptions!$C$63 | I34: =I33*Assumptions!$C$63 | J34: ＝平均余额×利率(按期末余额重算的隐含值; 与采用值(第4轮迭代输出)之差见下方残差行)
A36: · 长期借款 (计划还款+sweep第二顺位)
A37: 期初余额 | E37: =D42 | F37: =E42 | G37: =F42 | H37: =G42 | I37: =H42 | J37: 上年期末
A38: 计划还款(输入) | E38: =Assumptions!C$60 | F38: =Assumptions!D$60 | G38: =Assumptions!E$60 | H38: =Assumptions!F$60 | I38: =Assumptions!G$60 | J38: ＝Assumptions rep_lt
A39: 实际还款(≤期初) | E39: =MIN(E38,E37) | F39: =MIN(F38,F37) | G39: =MIN(G38,G37) | H39: =MIN(H38,H37) | I39: =MIN(I38,I37) | J39: ＝MIN(计划还款, 期初余额); 防止债务清零后仍按计划额扣现金
A40: sweep前未偿余额 | E40: =E37-E39 | F40: =F37-F39 | G40: =G37-G39 | H40: =H37-H39 | I40: =I37-I39 | J40: ＝期初-实际还款+新增
A41: 现金sweep偿还 | E41: =MIN(E15-E23,E40) | F41: =MIN(F15-F23,F40) | G41: =MIN(G15-G23,G40) | H41: =MIN(H15-H23,H40) | I41: =MIN(I15-I23,I40) | J41: ＝MIN(可动用现金余额, sweep前未偿)
A42: 期末余额 | D42: =BS!D31 | E42: =E40-E41 | F42: =F40-F41 | G42: =G40-G41 | H42: =H40-H41 | I42: =I40-I41 | J42: ＝sweep前未偿-sweep
A43: 平均余额 | E43: =(E37+E42)/2 | F43: =(F37+F42)/2 | G43: =(G37+G42)/2 | H43: =(H37+H42)/2 | I43: =(I37+I42)/2 | J43: ＝(期初+期末)/2
A44: 利息支出 | E44: =E43*Assumptions!$C$64 | F44: =F43*Assumptions!$C$64 | G44: =G43*Assumptions!$C$64 | H44: =H43*Assumptions!$C$64 | I44: =I43*Assumptions!$C$64 | J44: ＝平均余额×利率(按期末余额重算的隐含值; 与采用值(第4轮迭代输出)之差见下方残差行)
...

Sheet Equity_Roll
A1: 中芯国际 — Equity_Roll 所有者权益滚动
A2: 单位: 美元百万元(财报口径) | 股本/资本公积/库存股/OCI持平滚动; 盈余公积按归母计提; 未分配=期初+归母-分红-盈余公积计提
A3: 项目 | B3: 2023A | C3: 2024A | D3: 2025A | E3: 2026E | F3: 2027E | G3: 2028E | H3: 2029E | I3: 2030E | J3: 备注
A5: 股本 | B5: 0 | C5: 31.9 | D5: 32 | E5: =D5 | F5: =E5 | G5: =F5 | H5: =G5 | I5: =H5 | J5: 预测持平(不考虑增发)
A6: 资本公积 | B6: 0 | C6: 14266.4 | D6: 14394.8 | E6: =D6 | F6: =E6 | G6: =F6 | H6: =G6 | I6: =H6 | J6: 预测持平
A7: 减: 库存股 | B7: 0 | C7: 0 | D7: 0 | E7: =D7 | F7: =E7 | G7: =F7 | H7: =G7 | I7: =H7 | J7: 预测持平
A8: 其他综合收益 | B8: 286.9 | C8: 142.5 | D8: 154.7 | E8: =D8 | F8: =E8 | G8: =F8 | H8: =G8 | I8: =H8 | J8: 预测持平(汇率/公允变动不预测)
A9: 盈余公积计提(流量) | E9: =IS!E20*Assumptions!$C$54 | F9: =IS!F20*Assumptions!$C$54 | G9: =IS!G20*Assumptions!$C$54 | H9: =IS!H20*Assumptions!$C$54 | I9: =IS!I20*Assumptions!$C$54 | J9: ＝当年归母×0% (Assumptions)
A10: 盈余公积(期末) | B10: 0 | C10: 0 | D10: 0 | E10: =D10+E9 | F10: =E10+F9 | G10: =F10+G9 | H10: =G10+H9 | I10: =H10+I9 | J10: ＝期初+计提
A11: 现金分红(流量, 引用) | E11: =Schedules!E26 | F11: =Schedules!F26 | G11: =Schedules!G26 | H11: =Schedules!H26 | I11: =Schedules!I26 | J11: ＝Schedules
A12: 未分配利润(期末) | B12: 0 | C12: 6173.1 | D12: 6858.2 | E12: =D12+IS!E20-E11-E9 | F12: =E12+IS!F20-F11-F9 | G12: =F12+IS!G20-G11-G9 | H12: =G12+IS!H20-H11-H9 | I12: =H12+IS!I20-I11-I9 | J12: ＝期初+归母净利-分红-盈余公积计提
A13: 其他权益项目(轧差, 引用BS) | B13: 5746.7 | C13: -0.1 | D13: 0 | E13: =D13 | F13: =E13 | G13: =F13 | H13: =G13 | I13: =H13 | J13: 含专项储备及换算尾差, 持平
A14: 归母所有者权益合计 | B14: =B5+B6-B7+B8+B10+B12+B13 | C14: =C5+C6-C7+C8+C10+C12+C13 | D14: =D5+D6-D7+D8+D10+D12+D13 | E14: =E5+E6-E7+E8+E10+E12+E13 | F14: =F5+F6-F7+F8+F10+F12+F13 | G14: =G5+G6-G7+G8+G10+G12+G13 | H14: =H5+H6-H7+H8+H10+H12+H13 | I14: =I5+I6-I7+I8+I10+I12+I13
A15: 少数股东权益 | B15: 0 | C15: 11255.8 | D15: 13580.9 | E15: =D15 | F15: =E15 | G15: =F15 | H15: =G15 | I15: =H15
A16: 所有者权益合计 | B16: =B14+B15 | C16: =C14+C15 | D16: =D14+D15 | E16: =E14+E15 | F16: =F14+F15 | G16: =G14+G15 | H16: =H14+H15 | I16: =I14+I15
A18: 稀释股数
A19: 基本股数(总股本, 百万股) | C19: =Assumptions!$C$8 | J19: ＝Assumptions总股本85.61亿股
A20: 稀释工具(可转债/期权等, 百万股) | C20: 0 | J20: 占位输入: 如有流通可转债/期权等稀释工具在此输入
A21: 稀释后股数(百万股) | C21: =C19+C20 | J21: DCF/相对估值/Scenarios每股口径统一引用本行

Sheet DCF
A1: 中芯国际 — DCF 绝对估值 (FCFF, 显性期2026-2030 + Gordon终值)
A2: 单位: 美元百万元(财报口径) | 估值基准日2026-08-17, 采用年中折现(mid-year convention: t=0.5/1.5/.../4.5); WACC/g引用Assumptions(采用值=IF(override为空,计算值,override))
A3: 项目 | E3: 2026E | F3: 2027E | G3: 2028E | H3: 2029E | I3: 2030E | J3: 备注
A4: EBIT | E4: =IS!E23 | F4: =IS!F23 | G4: =IS!G23 | H4: =IS!H23 | I4: =IS!I23 | J4: ＝IS: 利润总额+财务费用
A5: 税率 | E5: =Assumptions!C$33 | F5: =Assumptions!D$33 | G5: =Assumptions!E$33 | H5: =Assumptions!F$33 | I5: =Assumptions!G$33
A6: NOPAT = EBIT×(1-t) | E6: =E4*(1-E5) | F6: =F4*(1-F5) | G6: =G4*(1-G5) | H6: =H4*(1-H5) | I6: =I4*(1-I5)
A7: 加: D&A | E7: =PPE!E19 | F7: =PPE!F19 | G7: =PPE!G19 | H7: =PPE!H19 | I7: =PPE!I19
A8: 减: ΔNWC | E8: =Schedules!E18 | F8: =Schedules!F18 | G8: =Schedules!G18 | H8: =Schedules!H18 | I8: =Schedules!I18 | J8: NWC增加为现金流出
A9: 减: Capex | E9: =PPE!E14 | F9: =PPE!F14 | G9: =PPE!G14 | H9: =PPE!H14 | I9: =PPE!I14
A10: FCFF | E10: =E6+E7-E8-E9 | F10: =F6+F7-F8-F9 | G10: =G6+G7-G8-G9 | H10: =H6+H7-H8-H9 | I10: =I6+I7-I8-I9
A11: 折现年序(年中) | E11: 0.5 | F11: 1.5 | G11: 2.5 | H11: 3.5 | I11: 4.5 | J11: 年中折现(mid-year); 基准日2026-08-17, 近似年中收到现金流
A12: 折现因子 | E12: =1/(1+Assumptions!$C$82)^E11 | F12: =1/(1+Assumptions!$C$82)^F11 | G12: =1/(1+Assumptions!$C$82)^G11 | H12: =1/(1+Assumptions!$C$82)^H11 | I12: =1/(1+Assumptions!$C$82)^I11
A13: PV(FCFF) | E13: =E10*E12 | F13: =F10*F12 | G13: =G10*G12 | H13: =H10*H12 | I13: =I10*I12
A15: 显性期PV合计 (2026-2030) | D15: =SUM(E13:I13)
A16: 终值 TV (Gordon) | D16: =I10*(1+Assumptions!$C$83)/(Assumptions!$C$82-Assumptions!$C$83) | J16: ＝FCFF2030×(1+g)/(WACC-g)
A17: PV(终值) | D17: =D16*I12 | J17: 终值按t=4.5折现(与显性期最后一年一致)
A18: 企业价值 EV | D18: =D15+D17
A19: 加: 货币资金(2025A末) | D19: =BS!D4
A20: 加: 交易性金融资产(2025A末) | D20: =BS!D5
A21: 加: 其他权益工具投资(2025A末) | D21: =BS!D18 | J21: 2025A末15.3亿, 参股投资按账面值计入股权价值
A22: 减: 有息负债(2025A末) | D22: =-(BS!D22+BS!D28+BS!D31+BS!D32)
A23: 净现金调整合计 | D23: =D19+D20+D21+D22 | J23: 供Sensitivity/Scenarios页引用
A24: 股权价值 | D24: =D18+D23
A25: 每股价值 (元) | D25: =D24/Equity_Roll!$C$21 | J25: ＝股权价值/稀释股数(Equity_Roll页)
A26: 现价 (2026-08-17) | D26: =Assumptions!$C$7
A27: 隐含涨跌幅 | D27: =D25/D26-1
A28: 隐含2026E P/E | D28: =D24/IS!E20 | J28: ＝股权价值/2026E归母
A29: 隐含2026E EV/EBITDA | D29: =D18/(IS!E23+PPE!E19)
A30: 注: 估值基准日2026-08-17, 与2026财年现金流起点存在时间错位; 年中折现(t=0.5起)为该错位的标准近似处理, 不再单独做stub调整

Sheet FCFE
A1: 中芯国际 — FCFE 股权自由现金流估值 (Ke折现, 与FCFF双视图)
A2: 单位: 美元百万元(财报口径) | FCFE=归母净利+D&A-ΔNWC-Capex+净新增借款(FIN页调度); 按股权成本Ke折现(年中口径与DCF页一致), 直接得股权价值, 无需EV→Equity桥
A3: 项目 | E3: 2026E | F3: 2027E | G3: 2028E | H3: 2029E | I3: 2030E | J3: 备注
A4: 归母净利润 | E4: =IS!E20 | F4: =IS!F20 | G4: =IS!G20 | H4: =IS!H20 | I4: =IS!I20 | J4: ＝IS归母净利(含FIN调度后的利息)
A5: 加: D&A | E5: =PPE!E19 | F5: =PPE!F19 | G5: =PPE!G19 | H5: =PPE!H19 | I5: =PPE!I19 | J5: ＝PP&E页折旧+无形摊销
A6: 减: ΔNWC | E6: =Schedules!E18 | F6: =Schedules!F18 | G6: =Schedules!G18 | H6: =Schedules!H18 | I6: =Schedules!I18 | J6: ＝Schedules; NWC增加为现金流出
A7: 减: Capex | E7: =PPE!E14 | F7: =PPE!F14 | G7: =PPE!G14 | H7: =PPE!H14 | I7: =PPE!I14 | J7: ＝PP&E页资本开支
A8: 加: 净新增借款 | E8: =FIN!E57 | F8: =FIN!F57 | G8: =FIN!G57 | H8: =FIN!H57 | I8: =FIN!I57 | J8: ＝FIN四档债务期末-期初(revolver新增-sweep偿还-计划还款); 股权口径下债务净变动归股东
A9: FCFE | E9: =E4+E5-E6-E7+E8 | F9: =F4+F5-F6-F7+F8 | G9: =G4+G5-G6-G7+G8 | H9: =H4+H5-H6-H7+H8 | I9: =I4+I5-I6-I7+I8 | J9: ＝归母+D&A-ΔNWC-Capex+净新增借款
A10: 折现年序(年中) | E10: 0.5 | F10: 1.5 | G10: 2.5 | H10: 3.5 | I10: 4.5 | J10: 年中折现, 与DCF页同口径
A11: 折现因子 (Ke) | E11: =1/(1+KE)^E10 | F11: =1/(1+KE)^F10 | G11: =1/(1+KE)^G10 | H11: =1/(1+KE)^H10 | I11: =1/(1+KE)^I10 | J11: ＝1/(1+Ke)^t; Ke为named range(Assumptions股权成本)
A12: PV(FCFE) | E12: =E9*E11 | F12: =F9*F11 | G12: =G9*G11 | H12: =H9*H11 | I12: =I9*I11
A14: 显性期PV合计 (2026-2030) | D14: =SUM(E12:I12)
A15: 终值 TV (Gordon) | D15: =I9*(1+TERM_G)/(KE-TERM_G) | J15: ＝FCFE2030×(1+g)/(Ke-g); Ke/g均为named range
A16: PV(终值) | D16: =D15*I11 | J16: 终值按t=4.5折现(与DCF页一致)
A17: 股权价值 (FCFE口径) | D17: =D14+D16 | J17: FCFE直接折现为股权价值, 无需净现金桥
A18: 每股价值 (元) | D18: =D17/SHARES_DIL | J18: ＝股权价值/稀释股数(named range)
A19: 对照: FCFF口径每股价值 (元) | D19: =DCF!D25 | J19: ＝DCF页主输出
A20: 两法差异 (FCFE/FCFF-1) | D20: =D18/D19-1 | J20: Checks页含一致性信息行
A21: 两法差异原因 | B21: ①折现率不同: FCFF按WACC(全资本成本, 税盾在分母)折现, FCFE按Ke(纯股权成本)折现; ②口径不同: FCFF为企业自由现金流, 须经EV→Equity桥加回净现金/扣有息负债, FCFE已含净新增借款、直接对应股权; ③杠杆路径不同: FCFE逐年反映FIN页revolver/sweep实际债务调度(资本结构动态变化), FCFF隐含目标结构(Wd)恒定; ④两法在"恒定资本结构+一致税盾处理"下理论等价, 实务差异主要来自债务调度时点、净现金桥与折现率差; 差异幅度大时应复查融资假设

Sheet Relative_Val
A1: 中芯国际 — Relative_Val 可比公司相对估值 + Beta unlever/relever
A2: 市值/PE-TTM为2026-08-17收盘(腾讯行情); 预测归母为一致预期/分析师输入; L-O列: βl/(1+(1-t)D/E) unlever取中位→Assumptions按目标结构relever
A4: 公司 | B4: 代码 | C4: 市值(亿元) | D4: PE-TTM | E4: 2026E归母(亿) | F4: 2026E PE | G4: 2027E归母(亿) | H4: 2027E PE | I4: 26→27增速 | J4: PEG | K4: 数据来源 / 备注 | L4: βl(输入) | M4: D/E(输入) | N4: 税率(输入) | O4: βu(公式)
A5: 可比中位数(A股0家) | K5: 无可比公司配置(兜底模式): βu走Assumptions蓝色输入, 相对估值上下限=目标PE下限
A6: 中芯国际(现价) | B6: 00981.HK | C6: =Assumptions!$C$9/100 | D6: 120.51 | E6: =Assumptions!$C$13/100 | F6: =C6/E6 | G6: =Assumptions!$C$15/100 | H6: =C6/G6 | K6: 2026E/2027E归母=一致预期; 腾讯行情PE-TTM(港元口径, 2026-08-17)
A8: 中芯国际定价 (基于模型基准2026E归母)
A9: 目标PE下限 | C9: 25 | K9: 兜底默认: 25x(无可比清单); 建议补comps后取可比中位数为上界
A10: 目标PE上限 | C10: =C9 | K10: ＝目标PE下限(无可比公司配置, 兜底)
A11: 模型基准2026E归母(百万) | C11: =IS!E20
A12: 对应股价下限(元) | C12: =C9*C11/Equity_Roll!$C$21
A13: 对应股价上限(元) | C13: =C10*C11/Equity_Roll!$C$21
A14: 以一致预期2026E归母8.0亿计股价区间(元) | C14: =C9*Assumptions!$C$13/Equity_Roll!$C$21 | D14: =C10*Assumptions!$C$13/Equity_Roll!$C$21 | K14: 左=PE下限, 右=PE上限
A15: 相对现价9.6218元空间 | C15: =C12/Assumptions!$C$7-1 | D15: =C13/Assumptions!$C$7-1

Sheet Sensitivity
A1: 中芯国际 — Sensitivity 敏感性分析
A2: 单位: 元/股 | 矩阵轴为公式(自动对中WACC采用值/g), 两矩阵引用DCF页FCFF与Equity_Roll稀释股数; 另附DPO单维敏感性
A4: 矩阵一: DCF每股价值 — WACC × 永续增长率g (年中折现, 与DCF页同口径)
A5: WACC \ g | C5: =Assumptions!$C$83-0.0100 | D5: =Assumptions!$C$83-0.0050 | E5: =Assumptions!$C$83 | F5: =Assumptions!$C$83+0.0050 | G5: =Assumptions!$C$83+0.0100
B6: =Assumptions!$C$82-0.0100 | C6: =(DCF!$E$10/(1+$B6)^0.5+DCF!$F$10/(1+$B6)^1.5+DCF!$G$10/(1+$B6)^2.5+DCF!$H$10/(1+$B6)^3.5+DCF!$I$10/(1+$B6)^4.5+DCF!$I$10*(1+C$5)/($B6-C$5)/(1+$B6)^4.5+DCF!$D$23)/Equity_Roll!$C$21 | D6: =(DCF!$E$10/(1+$B6)^0.5+DCF!$F$10/(1+$B6)^1.5+DCF!$G$10/(1+$B6)^2.5+DCF!$H$10/(1+$B6)^3.5+DCF!$I$10/(1+$B6)^4.5+DCF!$I$10*(1+D$5)/($B6-D$5)/(1+$B6)^4.5+DCF!$D$23)/Equity_Roll!$C$21 | E6: =(DCF!$E$10/(1+$B6)^0.5+DCF!$F$10/(1+$B6)^1.5+DCF!$G$10/(1+$B6)^2.5+DCF!$H$10/(1+$B6)^3.5+DCF!$I$10/(1+$B6)^4.5+DCF!$I$10*(1+E$5)/($B6-E$5)/(1+$B6)^4.5+DCF!$D$23)/Equity_Roll!$C$21 | F6: =(DCF!$E$10/(1+$B6)^0.5+DCF!$F$10/(1+$B6)^1.5+DCF!$G$10/(1+$B6)^2.5+DCF!$H$10/(1+$B6)^3.5+DCF!$I$10/(1+$B6)^4.5+DCF!$I$10*(1+F$5)/($B6-F$5)/(1+$B6)^4.5+DCF!$D$23)/Equity_Roll!$C$21 | G6: =(DCF!$E$10/(1+$B6)^0.5+DCF!$F$10/(1+$B6)^1.5+DCF!$G$10/(1+$B6)^2.5+DCF!$H$10/(1+$B6)^3.5+DCF!$I$10/(1+$B6)^4.5+DCF!$I$10*(1+G$5)/($B6-G$5)/(1+$B6)^4.5+DCF!$D$23)/Equity_Roll!$C$21
B7: =Assumptions!$C$82-0.0050 | C7: =(DCF!$E$10/(1+$B7)^0.5+DCF!$F$10/(1+$B7)^1.5+DCF!$G$10/(1+$B7)^2.5+DCF!$H$10/(1+$B7)^3.5+DCF!$I$10/(1+$B7)^4.5+DCF!$I$10*(1+C$5)/($B7-C$5)/(1+$B7)^4.5+DCF!$D$23)/Equity_Roll!$C$21 | D7: =(DCF!$E$10/(1+$B7)^0.5+DCF!$F$10/(1+$B7)^1.5+DCF!$G$10/(1+$B7)^2.5+DCF!$H$10/(1+$B7)^3.5+DCF!$I$10/(1+$B7)^4.5+DCF!$I$10*(1+D$5)/($B7-D$5)/(1+$B7)^4.5+DCF!$D$23)/Equity_Roll!$C$21 | E7: =(DCF!$E$10/(1+$B7)^0.5+DCF!$F$10/(1+$B7)^1.5+DCF!$G$10/(1+$B7)^2.5+DCF!$H$10/(1+$B7)^3.5+DCF!$I$10/(1+$B7)^4.5+DCF!$I$10*(1+E$5)/($B7-E$5)/(1+$B7)^4.5+DCF!$D$23)/Equity_Roll!$C$21 | F7: =(DCF!$E$10/(1+$B7)^0.5+DCF!$F$10/(1+$B7)^1.5+DCF!$G$10/(1+$B7)^2.5+DCF!$H$10/(1+$B7)^3.5+DCF!$I$10/(1+$B7)^4.5+DCF!$I$10*(1+F$5)/($B7-F$5)/(1+$B7)^4.5+DCF!$D$23)/Equity_Roll!$C$21 | G7: =(DCF!$E$10/(1+$B7)^0.5+DCF!$F$10/(1+$B7)^1.5+DCF!$G$10/(1+$B7)^2.5+DCF!$H$10/(1+$B7)^3.5+DCF!$I$10/(1+$B7)^4.5+DCF!$I$10*(1+G$5)/($B7-G$5)/(1+$B7)^4.5+DCF!$D$23)/Equity_Roll!$C$21
B8: =Assumptions!$C$82 | C8: =(DCF!$E$10/(1+$B8)^0.5+DCF!$F$10/(1+$B8)^1.5+DCF!$G$10/(1+$B8)^2.5+DCF!$H$10/(1+$B8)^3.5+DCF!$I$10/(1+$B8)^4.5+DCF!$I$10*(1+C$5)/($B8-C$5)/(1+$B8)^4.5+DCF!$D$23)/Equity_Roll!$C$21 | D8: =(DCF!$E$10/(1+$B8)^0.5+DCF!$F$10/(1+$B8)^1.5+DCF!$G$10/(1+$B8)^2.5+DCF!$H$10/(1+$B8)^3.5+DCF!$I$10/(1+$B8)^4.5+DCF!$I$10*(1+D$5)/($B8-D$5)/(1+$B8)^4.5+DCF!$D$23)/Equity_Roll!$C$21 | E8: =(DCF!$E$10/(1+$B8)^0.5+DCF!$F$10/(1+$B8)^1.5+DCF!$G$10/(1+$B8)^2.5+DCF!$H$10/(1+$B8)^3.5+DCF!$I$10/(1+$B8)^4.5+DCF!$I$10*(1+E$5)/($B8-E$5)/(1+$B8)^4.5+DCF!$D$23)/Equity_Roll!$C$21 | F8: =(DCF!$E$10/(1+$B8)^0.5+DCF!$F$10/(1+$B8)^1.5+DCF!$G$10/(1+$B8)^2.5+DCF!$H$10/(1+$B8)^3.5+DCF!$I$10/(1+$B8)^4.5+DCF!$I$10*(1+F$5)/($B8-F$5)/(1+$B8)^4.5+DCF!$D$23)/Equity_Roll!$C$21 | G8: =(DCF!$E$10/(1+$B8)^0.5+DCF!$F$10/(1+$B8)^1.5+DCF!$G$10/(1+$B8)^2.5+DCF!$H$10/(1+$B8)^3.5+DCF!$I$10/(1+$B8)^4.5+DCF!$I$10*(1+G$5)/($B8-G$5)/(1+$B8)^4.5+DCF!$D$23)/Equity_Roll!$C$21
B9: =Assumptions!$C$82+0.0050 | C9: =(DCF!$E$10/(1+$B9)^0.5+DCF!$F$10/(1+$B9)^1.5+DCF!$G$10/(1+$B9)^2.5+DCF!$H$10/(1+$B9)^3.5+DCF!$I$10/(1+$B9)^4.5+DCF!$I$10*(1+C$5)/($B9-C$5)/(1+$B9)^4.5+DCF!$D$23)/Equity_Roll!$C$21 | D9: =(DCF!$E$10/(1+$B9)^0.5+DCF!$F$10/(1+$B9)^1.5+DCF!$G$10/(1+$B9)^2.5+DCF!$H$10/(1+$B9)^3.5+DCF!$I$10/(1+$B9)^4.5+DCF!$I$10*(1+D$5)/($B9-D$5)/(1+$B9)^4.5+DCF!$D$23)/Equity_Roll!$C$21 | E9: =(DCF!$E$10/(1+$B9)^0.5+DCF!$F$10/(1+$B9)^1.5+DCF!$G$10/(1+$B9)^2.5+DCF!$H$10/(1+$B9)^3.5+DCF!$I$10/(1+$B9)^4.5+DCF!$I$10*(1+E$5)/($B9-E$5)/(1+$B9)^4.5+DCF!$D$23)/Equity_Roll!$C$21 | F9: =(DCF!$E$10/(1+$B9)^0.5+DCF!$F$10/(1+$B9)^1.5+DCF!$G$10/(1+$B9)^2.5+DCF!$H$10/(1+$B9)^3.5+DCF!$I$10/(1+$B9)^4.5+DCF!$I$10*(1+F$5)/($B9-F$5)/(1+$B9)^4.5+DCF!$D$23)/Equity_Roll!$C$21 | G9: =(DCF!$E$10/(1+$B9)^0.5+DCF!$F$10/(1+$B9)^1.5+DCF!$G$10/(1+$B9)^2.5+DCF!$H$10/(1+$B9)^3.5+DCF!$I$10/(1+$B9)^4.5+DCF!$I$10*(1+G$5)/($B9-G$5)/(1+$B9)^4.5+DCF!$D$23)/Equity_Roll!$C$21
B10: =Assumptions!$C$82+0.0100 | C10: =(DCF!$E$10/(1+$B10)^0.5+DCF!$F$10/(1+$B10)^1.5+DCF!$G$10/(1+$B10)^2.5+DCF!$H$10/(1+$B10)^3.5+DCF!$I$10/(1+$B10)^4.5+DCF!$I$10*(1+C$5)/($B10-C$5)/(1+$B10)^4.5+DCF!$D$23)/Equity_Roll!$C$21 | D10: =(DCF!$E$10/(1+$B10)^0.5+DCF!$F$10/(1+$B10)^1.5+DCF!$G$10/(1+$B10)^2.5+DCF!$H$10/(1+$B10)^3.5+DCF!$I$10/(1+$B10)^4.5+DCF!$I$10*(1+D$5)/($B10-D$5)/(1+$B10)^4.5+DCF!$D$23)/Equity_Roll!$C$21 | E10: =(DCF!$E$10/(1+$B10)^0.5+DCF!$F$10/(1+$B10)^1.5+DCF!$G$10/(1+$B10)^2.5+DCF!$H$10/(1+$B10)^3.5+DCF!$I$10/(1+$B10)^4.5+DCF!$I$10*(1+E$5)/($B10-E$5)/(1+$B10)^4.5+DCF!$D$23)/Equity_Roll!$C$21 | F10: =(DCF!$E$10/(1+$B10)^0.5+DCF!$F$10/(1+$B10)^1.5+DCF!$G$10/(1+$B10)^2.5+DCF!$H$10/(1+$B10)^3.5+DCF!$I$10/(1+$B10)^4.5+DCF!$I$10*(1+F$5)/($B10-F$5)/(1+$B10)^4.5+DCF!$D$23)/Equity_Roll!$C$21 | G10: =(DCF!$E$10/(1+$B10)^0.5+DCF!$F$10/(1+$B10)^1.5+DCF!$G$10/(1+$B10)^2.5+DCF!$H$10/(1+$B10)^3.5+DCF!$I$10/(1+$B10)^4.5+DCF!$I$10*(1+G$5)/($B10-G$5)/(1+$B10)^4.5+DCF!$D$23)/Equity_Roll!$C$21
A11: 高亮格=当前采用值(WACC/g轴自动对中); 与DCF页同为年中折现口径
A13: 矩阵二: 股价 — 2026E归母增速 × 目标PE (2025A归母685百万为基数)
A14: 2026E归母增速 \ PE | C14: 25 | D14: 30 | E14: 35 | F14: 40 | G14: 45 | H14: 50
B15: 0.4 | C15: =IS!$D$20*(1+$B15)*C$14/Equity_Roll!$C$21 | D15: =IS!$D$20*(1+$B15)*D$14/Equity_Roll!$C$21 | E15: =IS!$D$20*(1+$B15)*E$14/Equity_Roll!$C$21 | F15: =IS!$D$20*(1+$B15)*F$14/Equity_Roll!$C$21 | G15: =IS!$D$20*(1+$B15)*G$14/Equity_Roll!$C$21 | H15: =IS!$D$20*(1+$B15)*H$14/Equity_Roll!$C$21
B16: 0.6 | C16: =IS!$D$20*(1+$B16)*C$14/Equity_Roll!$C$21 | D16: =IS!$D$20*(1+$B16)*D$14/Equity_Roll!$C$21 | E16: =IS!$D$20*(1+$B16)*E$14/Equity_Roll!$C$21 | F16: =IS!$D$20*(1+$B16)*F$14/Equity_Roll!$C$21 | G16: =IS!$D$20*(1+$B16)*G$14/Equity_Roll!$C$21 | H16: =IS!$D$20*(1+$B16)*H$14/Equity_Roll!$C$21
B17: 0.8 | C17: =IS!$D$20*(1+$B17)*C$14/Equity_Roll!$C$21 | D17: =IS!$D$20*(1+$B17)*D$14/Equity_Roll!$C$21 | E17: =IS!$D$20*(1+$B17)*E$14/Equity_Roll!$C$21 | F17: =IS!$D$20*(1+$B17)*F$14/Equity_Roll!$C$21 | G17: =IS!$D$20*(1+$B17)*G$14/Equity_Roll!$C$21 | H17: =IS!$D$20*(1+$B17)*H$14/Equity_Roll!$C$21
B18: 1 | C18: =IS!$D$20*(1+$B18)*C$14/Equity_Roll!$C$21 | D18: =IS!$D$20*(1+$B18)*D$14/Equity_Roll!$C$21 | E18: =IS!$D$20*(1+$B18)*E$14/Equity_Roll!$C$21 | F18: =IS!$D$20*(1+$B18)*F$14/Equity_Roll!$C$21 | G18: =IS!$D$20*(1+$B18)*G$14/Equity_Roll!$C$21 | H18: =IS!$D$20*(1+$B18)*H$14/Equity_Roll!$C$21
B19: 1.115 | C19: =IS!$D$20*(1+$B19)*C$14/Equity_Roll!$C$21 | D19: =IS!$D$20*(1+$B19)*D$14/Equity_Roll!$C$21 | E19: =IS!$D$20*(1+$B19)*E$14/Equity_Roll!$C$21 | F19: =IS!$D$20*(1+$B19)*F$14/Equity_Roll!$C$21 | G19: =IS!$D$20*(1+$B19)*G$14/Equity_Roll!$C$21 | H19: =IS!$D$20*(1+$B19)*H$14/Equity_Roll!$C$21
B20: 1.3 | C20: =IS!$D$20*(1+$B20)*C$14/Equity_Roll!$C$21 | D20: =IS!$D$20*(1+$B20)*D$14/Equity_Roll!$C$21 | E20: =IS!$D$20*(1+$B20)*E$14/Equity_Roll!$C$21 | F20: =IS!$D$20*(1+$B20)*F$14/Equity_Roll!$C$21 | G20: =IS!$D$20*(1+$B20)*G$14/Equity_Roll!$C$21 | H20: =IS!$D$20*(1+$B20)*H$14/Equity_Roll!$C$21
A21: 高亮行≈一致预期增速; 矩阵与DCF独立, 供交叉验证
A23: 矩阵三: DPO单维敏感性 — 应付天数变动 × DCF每股价值
A24: DPO变动(天) \ 每股价值 | C24: 每股价值(元) | D24: vs基准 | I24: 机制: DPO变动δ→应付变动→ΔNWC变动→FCFF一阶调整; 未反映利息二阶效应(金额小); δ=0格=DCF基准
B25: -40 | C25: =((DCF!E$10+$B25/365*(IS!E$6-IS!D$6))/(1+Assumptions!$C$82)^0.5+(DCF!F$10+$B25/365*(IS!F$6-IS!E$6))/(1+Assumptions!$C$82)^1.5+(DCF!G$10+$B25/365*(IS!G$6-IS!F$6))/(1+Assumptions!$C$82)^2.5+(DCF!H$10+$B25/365*(IS!H$6-IS!G$6))/(1+Assumptions!$C$82)^3.5+(DCF!I$10+$B25/365*(IS!I$6-IS!H$6))/(1+Assumptions!$C$82)^4.5+(DCF!$I$10+$B25/365*(IS!I$6-IS!H$6))*(1+Assumptions!$C$83)/(Assumptions!$C$82-Assumptions!$C$83)/(1+Assumptions!$C$82)^4.5+DCF!$D$23)/Equity_Roll!$C$21 | D25: =C25/DCF!$D$25-1
B26: -20 | C26: =((DCF!E$10+$B26/365*(IS!E$6-IS!D$6))/(1+Assumptions!$C$82)^0.5+(DCF!F$10+$B26/365*(IS!F$6-IS!E$6))/(1+Assumptions!$C$82)^1.5+(DCF!G$10+$B26/365*(IS!G$6-IS!F$6))/(1+Assumptions!$C$82)^2.5+(DCF!H$10+$B26/365*(IS!H$6-IS!G$6))/(1+Assumptions!$C$82)^3.5+(DCF!I$10+$B26/365*(IS!I$6-IS!H$6))/(1+Assumptions!$C$82)^4.5+(DCF!$I$10+$B26/365*(IS!I$6-IS!H$6))*(1+Assumptions!$C$83)/(Assumptions!$C$82-Assumptions!$C$83)/(1+Assumptions!$C$82)^4.5+DCF!$D$23)/Equity_Roll!$C$21 | D26: =C26/DCF!$D$25-1
B27: 0 | C27: =((DCF!E$10+$B27/365*(IS!E$6-IS!D$6))/(1+Assumptions!$C$82)^0.5+(DCF!F$10+$B27/365*(IS!F$6-IS!E$6))/(1+Assumptions!$C$82)^1.5+(DCF!G$10+$B27/365*(IS!G$6-IS!F$6))/(1+Assumptions!$C$82)^2.5+(DCF!H$10+$B27/365*(IS!H$6-IS!G$6))/(1+Assumptions!$C$82)^3.5+(DCF!I$10+$B27/365*(IS!I$6-IS!H$6))/(1+Assumptions!$C$82)^4.5+(DCF!$I$10+$B27/365*(IS!I$6-IS!H$6))*(1+Assumptions!$C$83)/(Assumptions!$C$82-Assumptions!$C$83)/(1+Assumptions!$C$82)^4.5+DCF!$D$23)/Equity_Roll!$C$21 | D27: =C27/DCF!$D$25-1
B28: 20 | C28: =((DCF!E$10+$B28/365*(IS!E$6-IS!D$6))/(1+Assumptions!$C$82)^0.5+(DCF!F$10+$B28/365*(IS!F$6-IS!E$6))/(1+Assumptions!$C$82)^1.5+(DCF!G$10+$B28/365*(IS!G$6-IS!F$6))/(1+Assumptions!$C$82)^2.5+(DCF!H$10+$B28/365*(IS!H$6-IS!G$6))/(1+Assumptions!$C$82)^3.5+(DCF!I$10+$B28/365*(IS!I$6-IS!H$6))/(1+Assumptions!$C$82)^4.5+(DCF!$I$10+$B28/365*(IS!I$6-IS!H$6))*(1+Assumptions!$C$83)/(Assumptions!$C$82-Assumptions!$C$83)/(1+Assumptions!$C$82)^4.5+DCF!$D$23)/Equity_Roll!$C$21 | D28: =C28/DCF!$D$25-1
B29: 40 | C29: =((DCF!E$10+$B29/365*(IS!E$6-IS!D$6))/(1+Assumptions!$C$82)^0.5+(DCF!F$10+$B29/365*(IS!F$6-IS!E$6))/(1+Assumptions!$C$82)^1.5+(DCF!G$10+$B29/365*(IS!G$6-IS!F$6))/(1+Assumptions!$C$82)^2.5+(DCF!H$10+$B29/365*(IS!H$6-IS!G$6))/(1+Assumptions!$C$82)^3.5+(DCF!I$10+$B29/365*(IS!I$6-IS!H$6))/(1+Assumptions!$C$82)^4.5+(DCF!$I$10+$B29/365*(IS!I$6-IS!H$6))*(1+Assumptions!$C$83)/(Assumptions!$C$82-Assumptions!$C$83)/(1+Assumptions!$C$82)^4.5+DCF!$D$23)/Equity_Roll!$C$21 | D29: =C29/DCF!$D$25-1
A30: DPO每±20天≈FCFF±(Δ营业成本×20/365); 基准DPO路径见Assumptions(147→147天)

Sheet Scenarios
A1: 中芯国际 — Scenarios 熊/基/牛三情景估值
A2: 单位: 美元百万元(财报口径) | 基准估值=主模型输出(DCF页/IS页直接引用); 熊/牛保留简化净利率法并附桥接说明; 折现为年中口径与DCF一致
A3: 情景开关当前值 | B3: =Assumptions!$C$5 | C3: =CHOOSE(B3,"熊市","基准","牛市") | J3: 主模型(IS/BS/CF/FIN/DCF)随开关切换; 本页基准=主模型当前输出, 熊/牛为独立简化演算
A4: 基准NWC/收入密度ρ | B4: =Schedules!E17/IS!E4 | J4: 情景页ΔNWC=收入增量×ρ(负密度=现金流来源); 仅熊/牛简化法使用
A6: 熊市 Bear — 收入增速调整/净利率调整引用Assumptions第87行
A7: 项目 | E7: 2026E | F7: 2027E | G7: 2028E | H7: 2029E | I7: 2030E
A8: 营业收入 | E8: =IS!D4*(1+Revenue_Segments!E21+Assumptions!$C$87) | F8: =E8*(1+Revenue_Segments!F21+Assumptions!$C$87) | G8: =F8*(1+Revenue_Segments!G21+Assumptions!$C$87) | H8: =G8*(1+Revenue_Segments!H21+Assumptions!$C$87) | I8: =H8*(1+Revenue_Segments!I21+Assumptions!$C$87)
A9: 归母净利率 | E9: =(Revenue_Segments!E22+Assumptions!$D$87-Assumptions!C$27-Assumptions!C$28-Assumptions!C$29-Assumptions!C$30-Assumptions!$C$34)*(1-Assumptions!C$33) | F9: =(Revenue_Segments!F22+Assumptions!$D$87-Assumptions!D$27-Assumptions!D$28-Assumptions!D$29-Assumptions!D$30-Assumptions!$C$34)*(1-Assumptions!D$33) | G9: =(Revenue_Segments!G22+Assumptions!$D$87-Assumptions!E$27-Assumptions!E$28-Assumptions!E$29-Assumptions!E$30-Assumptions!$C$34)*(1-Assumptions!E$33) | H9: =(Revenue_Segments!H22+Assumptions!$D$87-Assumptions!F$27-Assumptions!F$28-Assumptions!F$29-Assumptions!F$30-Assumptions!$C$34)*(1-Assumptions!F$33) | I9: =(Revenue_Segments!I22+Assumptions!$D$87-Assumptions!G$27-Assumptions!G$28-Assumptions!G$29-Assumptions!G$30-Assumptions!$C$34)*(1-Assumptions!G$33)
A10: 归母净利润 | E10: =E8*E9 | F10: =F8*F9 | G10: =G8*G9 | H10: =H8*H9 | I10: =I8*I9
A11: FCFF (简化) | E11: =E10+PPE!E19-(E8-IS!D4)*$B$4-PPE!E14 | F11: =F10+PPE!F19-(F8-E8)*$B$4-PPE!F14 | G11: =G10+PPE!G19-(G8-F8)*$B$4-PPE!G14 | H11: =H10+PPE!H19-(H8-G8)*$B$4-PPE!H14 | I11: =I10+PPE!I19-(I8-H8)*$B$4-PPE!I14
A12: DCF每股价值(元, 简化法) | B12: =(E11/(1+Assumptions!$C$82)^0.5+F11/(1+Assumptions!$C$82)^1.5+G11/(1+Assumptions!$C$82)^2.5+H11/(1+Assumptions!$C$82)^3.5+I11/(1+Assumptions!$C$82)^4.5+I11*(1+Assumptions!$C$83)/(Assumptions!$C$82-Assumptions!$C$83)/(1+Assumptions!$C$82)^4.5+DCF!$D$23)/Equity_Roll!$C$21 | J12: 简化净利率法+年中折现; WACC/g/净现金调整与DCF页一致; 与主模型差异见基准块桥接说明
A13: 相对估值股价(元) | B13: =E10*Relative_Val!$C$9/Equity_Roll!$C$21 | J13: ＝情景2026E归母×可比中位2026E PE/稀释股数
A15: 基准 Base — 收入增速调整/净利率调整引用Assumptions第88行
A16: 项目 | E16: 2026E | F16: 2027E | G16: 2028E | H16: 2029E | I16: 2030E
A17: 营业收入 | E17: =IS!D4*(1+Revenue_Segments!E21+Assumptions!$C$88) | F17: =E17*(1+Revenue_Segments!F21+Assumptions!$C$88) | G17: =F17*(1+Revenue_Segments!G21+Assumptions!$C$88) | H17: =G17*(1+Revenue_Segments!H21+Assumptions!$C$88) | I17: =H17*(1+Revenue_Segments!I21+Assumptions!$C$88)
A18: 归母净利率 | E18: =(Revenue_Segments!E22+Assumptions!$D$88-Assumptions!C$27-Assumptions!C$28-Assumptions!C$29-Assumptions!C$30-Assumptions!$C$34)*(1-Assumptions!C$33) | F18: =(Revenue_Segments!F22+Assumptions!$D$88-Assumptions!D$27-Assumptions!D$28-Assumptions!D$29-Assumptions!D$30-Assumptions!$C$34)*(1-Assumptions!D$33) | G18: =(Revenue_Segments!G22+Assumptions!$D$88-Assumptions!E$27-Assumptions!E$28-Assumptions!E$29-Assumptions!E$30-Assumptions!$C$34)*(1-Assumptions!E$33) | H18: =(Revenue_Segments!H22+Assumptions!$D$88-Assumptions!F$27-Assumptions!F$28-Assumptions!F$29-Assumptions!F$30-Assumptions!$C$34)*(1-Assumptions!F$33) | I18: =(Revenue_Segments!I22+Assumptions!$D$88-Assumptions!G$27-Assumptions!G$28-Assumptions!G$29-Assumptions!G$30-Assumptions!$C$34)*(1-Assumptions!G$33)
A19: 归母净利润 | E19: =E17*E18 | F19: =F17*F18 | G19: =G17*G18 | H19: =H17*H18 | I19: =I17*I18
A20: FCFF (简化) | E20: =E19+PPE!E19-(E17-IS!D4)*$B$4-PPE!E14 | F20: =F19+PPE!F19-(F17-E17)*$B$4-PPE!F14 | G20: =G19+PPE!G19-(G17-F17)*$B$4-PPE!G14 | H20: =H19+PPE!H19-(H17-G17)*$B$4-PPE!H14 | I20: =I19+PPE!I19-(I17-H17)*$B$4-PPE!I14
A21: DCF每股价值(元) =主模型 | B21: =DCF!D25 | J21: 基准直接引用主模型DCF输出(情景开关=2时即基准口径), 不再独立演算
A22: 相对估值股价(元) =主模型归母 | B22: =IS!E20*Relative_Val!$C$9/Equity_Roll!$C$21 | J22: ＝主模型2026E归母(IS)×可比中位2026E PE/稀释股数
A23: 桥接说明: 上方基准收入/净利率/FCFF行为简化法演算(供与熊/牛同口径对比), 其估值行已被主模型输出替代; 简化法与主模型的差异主要来自: ①财务费用(主模型=FIN平均余额计息, 简化法=固定费用率) ②ΔNWC(主模型=逐项天数驱动, 简化法=密度ρ近似) ③折旧/资本开支口径一致
A25: 牛市 Bull — 收入增速调整/净利率调整引用Assumptions第89行
A26: 项目 | E26: 2026E | F26: 2027E | G26: 2028E | H26: 2029E | I26: 2030E
A27: 营业收入 | E27: =IS!D4*(1+Revenue_Segments!E21+Assumptions!$C$89) | F27: =E27*(1+Revenue_Segments!F21+Assumptions!$C$89) | G27: =F27*(1+Revenue_Segments!G21+Assumptions!$C$89) | H27: =G27*(1+Revenue_Segments!H21+Assumptions!$C$89) | I27: =H27*(1+Revenue_Segments!I21+Assumptions!$C$89)
A28: 归母净利率 | E28: =(Revenue_Segments!E22+Assumptions!$D$89-Assumptions!C$27-Assumptions!C$28-Assumptions!C$29-Assumptions!C$30-Assumptions!$C$34)*(1-Assumptions!C$33) | F28: =(Revenue_Segments!F22+Assumptions!$D$89-Assumptions!D$27-Assumptions!D$28-Assumptions!D$29-Assumptions!D$30-Assumptions!$C$34)*(1-Assumptions!D$33) | G28: =(Revenue_Segments!G22+Assumptions!$D$89-Assumptions!E$27-Assumptions!E$28-Assumptions!E$29-Assumptions!E$30-Assumptions!$C$34)*(1-Assumptions!E$33) | H28: =(Revenue_Segments!H22+Assumptions!$D$89-Assumptions!F$27-Assumptions!F$28-Assumptions!F$29-Assumptions!F$30-Assumptions!$C$34)*(1-Assumptions!F$33) | I28: =(Revenue_Segments!I22+Assumptions!$D$89-Assumptions!G$27-Assumptions!G$28-Assumptions!G$29-Assumptions!G$30-Assumptions!$C$34)*(1-Assumptions!G$33)
A29: 归母净利润 | E29: =E27*E28 | F29: =F27*F28 | G29: =G27*G28 | H29: =H27*H28 | I29: =I27*I28
A30: FCFF (简化) | E30: =E29+PPE!E19-(E27-IS!D4)*$B$4-PPE!E14 | F30: =F29+PPE!F19-(F27-E27)*$B$4-PPE!F14 | G30: =G29+PPE!G19-(G27-F27)*$B$4-PPE!G14 | H30: =H29+PPE!H19-(H27-G27)*$B$4-PPE!H14 | I30: =I29+PPE!I19-(I27-H27)*$B$4-PPE!I14
A31: DCF每股价值(元, 简化法) | B31: =(E30/(1+Assumptions!$C$82)^0.5+F30/(1+Assumptions!$C$82)^1.5+G30/(1+Assumptions!$C$82)^2.5+H30/(1+Assumptions!$C$82)^3.5+I30/(1+Assumptions!$C$82)^4.5+I30*(1+Assumptions!$C$83)/(Assumptions!$C$82-Assumptions!$C$83)/(1+Assumptions!$C$82)^4.5+DCF!$D$23)/Equity_Roll!$C$21 | J31: 简化净利率法+年中折现; WACC/g/净现金调整与DCF页一致; 与主模型差异见基准块桥接说明
A32: 相对估值股价(元) | B32: =E29*Relative_Val!$C$9/Equity_Roll!$C$21 | J32: ＝情景2026E归母×可比中位2026E PE/稀释股数
A34: 三情景汇总
